Workbook
Name NativeTimeline_F._FIN: #N/A
Name SegmentaciónDeDatos_AÑO: #N/A
Name SegmentaciónDeDatos_MES: #N/A

Sheet Dashboard

Sheet TD 2024
AN1: Top 5
B2: Mes. | C2: Total | E2: Mes | F2: Total | H2: Genero. | I2: Total | K2: Genero | L2: Total | N2: N. Dias Incap. | O2: Ttal. | Q2: N. Dias Inc. | S2: Clase de Inc. | T2: Cuenta de CLASE DE INCAPACIDAD | V2: Clase Inc. | W2: Total | Y2: Tipo de Inc. | Z2: Total | AB2: Tipo de Inc. | AC2: Total | AE2: Entidad | AF2: Ttal. | AH2: Entidad | AI2: Total | AK2: Descrip. | AL2: Total | AN2: Descrip. | AO2: Total | AQ2: Total | AR2: Etiquetas de columna | BB2: Cargos | BC2: Total | BE2: =BB2 -> Cargos | BF2: Total | BH2: Empresa Usuaria. | BI2: Total | BK2: =BH2 -> Empresa Usuaria. | BL2: Total | BN2: Área o Dpto. | BO2: Total. | BQ2: =BN2 -> Área o Dpto. | BR2: Total | BW2: =BT2 -> 0 | BX2: Total
B3: ENERO | C3: 10 | E3: ENERO | F3: =_xlfn.IFNA(VLOOKUP(E3,$B$3:$C$14,2,FALSE),"0") -> 10 | H3: HOMBRE | I3: 10 | K3: HOMBRE | L3: =_xlfn.IFNA(VLOOKUP(K3,$H$3:$I$14,2,FALSE),"0") -> 10 | N3: 1 | O3: 6 | Q3: =SUM(O3:O33) -> 124 | S3: ARL | T3: 1 | V3: ARL | W3: =_xlfn.IFNA(VLOOKUP(V3,$S$3:$T$14,2,FALSE),"0") -> 1 | Y3: ENFERMENDAD GENERAL | Z3: 18 | AB3: ENFERMENDAD GENERAL | AC3: =_xlfn.IFNA(VLOOKUP(AB3,$Y$3:$Z$14,2,FALSE),"0") -> 18 | AE3: CAJACOPI | AF3: 3 | AH3: CAFESALUD | AI3: =_xlfn.IFNA(VLOOKUP(AH3,$AE$3:$AF$17,2,FALSE),"0") -> 0 | AK3: Amigdalitis aguda, no especificada | AL3: 1 | AN3: Amigdalitis aguda, no especificada | AO3: =_xlfn.IFNA(VLOOKUP(AN3,$AK$3:$AL$7,2,FALSE),"0") -> 1 | AQ3: Descrip. | AR3: HOMBRE | AS3: MUJER | AW3: Entidad | AX3: Hombre | AY3: Mujer | AZ3: Total | BB3: AUXILIAR DE BODEGA | BC3: 2 | BE3: AMA DE LLAVES | BF3: =_xlfn.IFNA(VLOOKUP(BE3,$BB$3:$BC$48,2,FALSE),"0") -> 0 | BH3: COMFAMILIAR ATLANTICO | BI3: 20 | BK3: COMFAMILIAR ATLANTICO | BL3: =_xlfn.IFNA(VLOOKUP(BK3,$BH$3:$BI$10,2,FALSE),"0") -> 20 | BN3: CENTRO DE PROCESAMIENTO | BO3: 1 | BQ3: 40 MIL EMPLEOS | BR3: =_xlfn.IFNA(VLOOKUP(BQ3,$BN$3:$BO$44,2,FALSE),"0") -> 0 | BW3: =BT3 -> 0 | BX3: =BU3 -> 0
B4: MARZO | C4: 5 | E4: MARZO | F4: =_xlfn.IFNA(VLOOKUP(E4,$B$3:$C$14,2,FALSE),"0") -> 5 | H4: MUJER | I4: 10 | K4: MUJER | L4: =_xlfn.IFNA(VLOOKUP(K4,$H$3:$I$14,2,FALSE),"0") -> 10 | N4: 2 | O4: 14 | S4: EPS | T4: 19 | V4: EPS | W4: =_xlfn.IFNA(VLOOKUP(V4,$S$3:$T$14,2,FALSE),"0") -> 19 | Y4: ACCIDENTE DE TRANSITO | Z4: 1 | AB4: LICENCIA DE LUTO | AC4: =_xlfn.IFNA(VLOOKUP(AB4,$Y$3:$Z$14,2,FALSE),"0") -> 0 | AE4: COOSALUD | AF4: 1 | AH4: CAJACOPI | AI4: =_xlfn.IFNA(VLOOKUP(AH4,$AE$3:$AF$17,2,FALSE),"0") -> 3 | AK4: Contusion de la rodilla | AL4: 1 | AN4: Cefalea | AO4: =_xlfn.IFNA(VLOOKUP(AN4,$AK$3:$AL$7,2,FALSE),"0") -> 0 | AQ4: Amigdalitis aguda, no especificada | AR4: 1 | AW4: Amigdalitis aguda, no especificada | AX4: =_xlfn.IFNA(VLOOKUP(AW4,$AQ$4:$AS$328,2,FALSE),"0") -> 1 | AY4: =_xlfn.IFNA(VLOOKUP(AW4,$AQ$4:$AS$328,3,FALSE),"0") -> 0 | AZ4: =SUM(AX4:AY4) -> 1 | BB4: AUXILIAR DE COCINA | BC4: 1 | BE4: ASESOR COMERCIAL | BF4: =_xlfn.IFNA(VLOOKUP(BE4,$BB$3:$BC$48,2,FALSE),"0") -> 0 | BK4: EDIFICIO TESTA ROSA | BL4: =_xlfn.IFNA(VLOOKUP(BK4,$BH$3:$BI$10,2,FALSE),"0") -> 0 | BN4: CENTRO RECREACIONAL CLL 48 | BO4: 4 | BQ4: ASEO | BR4: =_xlfn.IFNA(VLOOKUP(BQ4,$BN$3:$BO$44,2,FALSE),"0") -> 0 | BW4: =BT4 -> 0 | BX4: =BU4 -> 0
B5: FEBRERO | C5: 5 | E5: ABRIL | F5: =_xlfn.IFNA(VLOOKUP(E5,$B$3:$C$14,2,FALSE),"0") -> 0 | K5: HOMBRE | L5: =L3/F15 -> 0.66666667 | M5: =1-L5 -> 0.33333333 | N5: 4 | O5: 4 | V5: =S5 -> 0 | W5: =_xlfn.IFNA(VLOOKUP(V5,$S$3:$T$14,2,FALSE),"0") -> 0 | Y5: ACCIDENTE LABORAL | Z5: 1 | AB5: LICENCIA DE MATERNIDAD | AC5: =_xlfn.IFNA(VLOOKUP(AB5,$Y$3:$Z$14,2,FALSE),"0") -> 0 | AE5: E.P.S SANITAS | AF5: 1 | AH5: COOMEVA | AI5: =_xlfn.IFNA(VLOOKUP(AH5,$AE$3:$AF$17,2,FALSE),"0") -> 0 | AK5: Otros dolores abdominales y los no especificados | AL5: 1 | AN5: Colico renal, no especificado | AO5: =_xlfn.IFNA(VLOOKUP(AN5,$AK$3:$AL$7,2,FALSE),"0") -> 0 | AQ5: Contusion de la rodilla | AS5: 1 | AW5: Cefalea | AX5: =_xlfn.IFNA(VLOOKUP(AW5,$AQ$4:$AS$328,2,FALSE),"0") -> 0 | AY5: =_xlfn.IFNA(VLOOKUP(AW5,$AQ$4:$AS$328,3,FALSE),"0") -> 0 | AZ5: =SUM(AX5:AY5) -> 0 | BB5: AYUDANTE COCINA | BC5: 6 | BE5: AUX GESTION DOCUMENTAL | BF5: =_xlfn.IFNA(VLOOKUP(BE5,$BB$3:$BC$48,2,FALSE),"0") -> 0 | BK5: MARTA LUCIA YEPES R. | BL5: =_xlfn.IFNA(VLOOKUP(BK5,$BH$3:$BI$10,2,FALSE),"0") -> 0 | BN5: CENTRO RECREACIONAL TURIPANA | BO5: 7 | BQ5: C. ATENCION C.48 | BR5: =_xlfn.IFNA(VLOOKUP(BQ5,$BN$3:$BO$44,2,FALSE),"0") -> 0 | BW5: =BT5 -> 0 | BX5: =BU5 -> 0
E6: MAYO | F6: =_xlfn.IFNA(VLOOKUP(E6,$B$3:$C$14,2,FALSE),"0") -> 0 | K6: MUJER | L6: =L4/F15 -> 0.66666667 | M6: =1-L6 -> 0.33333333 | N6: 7 | O6: 14 | AB6: LICENCIA DE PATERNIDAD | AC6: =_xlfn.IFNA(VLOOKUP(AB6,$Y$3:$Z$14,2,FALSE),"0") -> 0 | AE6: EPS/SURA | AF6: 2 | AH6: COOSALUD | AI6: =_xlfn.IFNA(VLOOKUP(AH6,$AE$3:$AF$17,2,FALSE),"0") -> 1 | AK6: Otras colitis y gastroenteritis no infecciosas especificadas | AL6: 2 | AN6: Contusion de la rodilla | AO6: =_xlfn.IFNA(VLOOKUP(AN6,$AK$3:$AL$7,2,FALSE),"0") -> 1 | AQ6: Otros dolores abdominales y los no especificados | AS6: 1 | AW6: Colico renal, no especificado | AX6: =_xlfn.IFNA(VLOOKUP(AW6,$AQ$4:$AS$328,2,FALSE),"0") -> 0 | AY6: =_xlfn.IFNA(VLOOKUP(AW6,$AQ$4:$AS$328,3,FALSE),"0") -> 0 | AZ6: =SUM(AX6:AY6) -> 0 | BB6: CHEF | BC6: 1 | BE6: AUX.INTERMEDIACION LABORAL | BF6: =_xlfn.IFNA(VLOOKUP(BE6,$BB$3:$BC$48,2,FALSE),"0") -> 0 | BK6: No Existe | BL6: =_xlfn.IFNA(VLOOKUP(BK6,$BH$3:$BI$10,2,FALSE),"0") -> 0 | BN6: SEDE CARIBE | BO6: 1 | BQ6: C. ATENCION VIA 40 | BR6: =_xlfn.IFNA(VLOOKUP(BQ6,$BN$3:$BO$44,2,FALSE),"0") -> 0 | BW6: =BT6 -> 0 | BX6: =BU6 -> 0
E7: JUNIO | F7: =_xlfn.IFNA(VLOOKUP(E7,$B$3:$C$14,2,FALSE),"0") -> 0 | N7: 15 | O7: 15 | AB7: ACCIDENTE DE TRANSITO | AC7: =_xlfn.IFNA(VLOOKUP(AB7,$Y$3:$Z$14,2,FALSE),"0") -> 1 | AE7: FAMISANAR | AF7: 3 | AH7: E.P.S SANITAS | AI7: =_xlfn.IFNA(VLOOKUP(AH7,$AE$3:$AF$17,2,FALSE),"0") -> 1 | AK7: Migrana con aura [migrana clasica] | AL7: 2 | AN7: Dengue sin signos de alarma | AO7: =_xlfn.IFNA(VLOOKUP(AN7,$AK$3:$AL$7,2,FALSE),"0") -> 0 | AQ7: Otras colitis y gastroenteritis no infecciosas especificadas | AS7: 2 | AW7: Contusion de la rodilla | AX7: =_xlfn.IFNA(VLOOKUP(AW7,$AQ$4:$AS$328,2,FALSE),"0") -> 0 | AY7: =_xlfn.IFNA(VLOOKUP(AW7,$AQ$4:$AS$328,3,FALSE),"0") -> 1 | AZ7: =SUM(AX7:AY7) -> 1 | BB7: COCINERO 1 | BC7: 3 | BE7: AUXILIAR | BF7: =_xlfn.IFNA(VLOOKUP(BE7,$BB$3:$BC$48,2,FALSE),"0") -> 0 | BK7: PLASDIBAR LTDA | BL7: =_xlfn.IFNA(VLOOKUP(BK7,$BH$3:$BI$10,2,FALSE),"0") -> 0 | BN7: SEDE CARIBE MERCADEO | BO7: 4 | BQ7: C.A. VIVA QUILLA | BR7: =_xlfn.IFNA(VLOOKUP(BQ7,$BN$3:$BO$44,2,FALSE),"0") -> 0 | BW7: =BT7 -> 0 | BX7: =BU7 -> 0
E8: JULIO | F8: =_xlfn.IFNA(VLOOKUP(E8,$B$3:$C$14,2,FALSE),"0") -> 0 | N8: 16 | O8: 16 | AB8: ACCIDENTE LABORAL | AC8: =_xlfn.IFNA(VLOOKUP(AB8,$Y$3:$Z$14,2,FALSE),"0") -> 1 | AE8: MUTUALSER | AF8: 1 | AH8: EPS/SURA | AI8: =_xlfn.IFNA(VLOOKUP(AH8,$AE$3:$AF$17,2,FALSE),"0") -> 2 | AK8: Dolor en el pecho, no especificado | AL8: 1 | AN8: Dientes incluidos | AO8: =_xlfn.IFNA(VLOOKUP(AN8,$AK$3:$AL$7,2,FALSE),"0") -> 0 | AQ8: Migrana con aura [migrana clasica] | AS8: 2 | AW8: Dengue sin signos de alarma | AX8: =_xlfn.IFNA(VLOOKUP(AW8,$AQ$4:$AS$328,2,FALSE),"0") -> 0 | AY8: =_xlfn.IFNA(VLOOKUP(AW8,$AQ$4:$AS$328,3,FALSE),"0") -> 0 | AZ8: =SUM(AX8:AY8) -> 0 | BB8: STEWARD | BC8: 1 | BE8: AUXILIAR CAPACITACION | BF8: =_xlfn.IFNA(VLOOKUP(BE8,$BB$3:$BC$48,2,FALSE),"0") -> 0 | BK8: TEMPOACTIVA EST S.A.S. | BL8: =_xlfn.IFNA(VLOOKUP(BK8,$BH$3:$BI$10,2,FALSE),"0") -> 0 | BN8: SEDE NORTE MERCADEO | BO8: 2 | BQ8: C.ATENCION C.82 | BR8: =_xlfn.IFNA(VLOOKUP(BQ8,$BN$3:$BO$44,2,FALSE),"0") -> 0 | BW8: =BT8 -> 0 | BX8: =BU8 -> 0
E9: AGOSTO | F9: =_xlfn.IFNA(VLOOKUP(E9,$B$3:$C$14,2,FALSE),"0") -> 0 | N9: 24 | O9: 24 | AB9: =Y9 -> 0 | AC9: =_xlfn.IFNA(VLOOKUP(AB9,$Y$3:$Z$14,2,FALSE),"0") -> 0 | AE9: NUEVA E.P.S. | AF9: 6 | AH9: FAMISANAR | AI9: =_xlfn.IFNA(VLOOKUP(AH9,$AE$3:$AF$17,2,FALSE),"0") -> 3 | AK9: Otros sindromes de cefalea especificados | AL9: 1 | AN9: Dolor abdominal localizado en parte superior | AO9: =_xlfn.IFNA(VLOOKUP(AN9,$AK$3:$AL$7,2,FALSE),"0") -> 0 | AQ9: Dolor en el pecho, no especificado | AR9: 1 | AW9: Dientes incluidos | AX9: =_xlfn.IFNA(VLOOKUP(AW9,$AQ$4:$AS$328,2,FALSE),"0") -> 0 | AY9: =_xlfn.IFNA(VLOOKUP(AW9,$AQ$4:$AS$328,3,FALSE),"0") -> 0 | AZ9: =SUM(AX9:AY9) -> 0 | BB9: SUPERNUMERARIO(A) | BC9: 6 | BE9: AUXILIAR DE ARCHIVO | BF9: =_xlfn.IFNA(VLOOKUP(BE9,$BB$3:$BC$48,2,FALSE),"0") -> 0 | BN9: TURIPANA MERCADEO | BO9: 1 | BQ9: C.ATENCION. C.76 | BR9: =_xlfn.IFNA(VLOOKUP(BQ9,$BN$3:$BO$44,2,FALSE),"0") -> 0 | BW9: =BT9 -> 0 | BX9: =BU9 -> 0
E10: SEPTIEMBRE | F10: =_xlfn.IFNA(VLOOKUP(E10,$B$3:$C$14,2,FALSE),"0") -> 0 | N10: 31 | O10: 31 | AE10: SALUD TOTAL | AF10: 3 | AH10: MEDIMAS | AI10: =_xlfn.IFNA(VLOOKUP(AH10,$AE$3:$AF$17,2,FALSE),"0") -> 0 | AK10: Dorsalgia, no especificada | AL10: 1 | AN10: Esguinces y torceduras del tobillo | AO10: =_xlfn.IFNA(VLOOKUP(AN10,$AK$3:$AL$7,2,FALSE),"0") -> 0 | AQ10: Otros sindromes de cefalea especificados | AR10: 1 | AW10: Dolor abdominal localizado en parte superior | AX10: =_xlfn.IFNA(VLOOKUP(AW10,$AQ$4:$AS$328,2,FALSE),"0") -> 0 | AY10: =_xlfn.IFNA(VLOOKUP(AW10,$AQ$4:$AS$328,3,FALSE),"0") -> 0 | AZ10: =SUM(AX10:AY10) -> 0 | BE10: AUXILIAR DE BAR | BF10: =_xlfn.IFNA(VLOOKUP(BE10,$BB$3:$BC$48,2,FALSE),"0") -> 0 | BQ10: C.R.U | BR10: =_xlfn.IFNA(VLOOKUP(BQ10,$BN$3:$BO$44,2,FALSE),"0") -> 0 | BW10: =BT10 -> 0 | BX10: =BU10 -> 0
E11: FEBRERO | F11: =_xlfn.IFNA(VLOOKUP(E11,$B$3:$C$14,2,FALSE),"0") -> 0 | AH11: MUTUALSER | AI11: =_xlfn.IFNA(VLOOKUP(AH11,$AE$3:$AF$17,2,FALSE),"0") -> 1 | AK11: Otros estados postquirurgicos especificados | AL11: 1 | AN11: Esguinces y torceduras que comprometen el ligamento cruzado (anterior) (posterior) de la rodilla | AO11: =_xlfn.IFNA(VLOOKUP(AN11,$AK$3:$AL$7,2,FALSE),"0") -> 0 | AQ11: Dorsalgia, no especificada | AR11: 1 | AW11: Esguinces y torceduras del tobillo | AX11: =_xlfn.IFNA(VLOOKUP(AW11,$AQ$4:$AS$328,2,FALSE),"0") -> 0 | AY11: =_xlfn.IFNA(VLOOKUP(AW11,$AQ$4:$AS$328,3,FALSE),"0") -> 0 | AZ11: =SUM(AX11:AY11) -> 0 | BE11: AUXILIAR DE BODEGA | BF11: =_xlfn.IFNA(VLOOKUP(BE11,$BB$3:$BC$48,2,FALSE),"0") -> 2 | BQ11: CENTRO DE ATENCION PIMSAS | BR11: =_xlfn.IFNA(VLOOKUP(BQ11,$BN$3:$BO$44,2,FALSE),"0") -> 0 | BW11: =BT11 -> 0 | BX11: =BU11 -> 0
E12: OCTUBRE | F12: =_xlfn.IFNA(VLOOKUP(E12,$B$3:$C$14,2,FALSE),"0") -> 0 | AH12: CONSORCIO SAYP | AI12: =_xlfn.IFNA(VLOOKUP(AH12,$AE$3:$AF$17,2,FALSE),"0") -> 0 | AK12: Fractura de otros huesos metacarpianos | AL12: 1 | AN12: Fiebre, no especificada | AO12: =_xlfn.IFNA(VLOOKUP(AN12,$AK$3:$AL$7,2,FALSE),"0") -> 0 | AQ12: Otros estados postquirurgicos especificados | AR12: 1 | AW12: Esguinces y torceduras que comprometen el ligamento cruzado (anterior) (posterior) de la rodilla | AX12: =_xlfn.IFNA(VLOOKUP(AW12,$AQ$4:$AS$328,2,FALSE),"0") -> 0 | AY12: =_xlfn.IFNA(VLOOKUP(AW12,$AQ$4:$AS$328,3,FALSE),"0") -> 0 | AZ12: =SUM(AX12:AY12) -> 0 | BE12: AUXILIAR DE COBRANZAS | BF12: =_xlfn.IFNA(VLOOKUP(BE12,$BB$3:$BC$48,2,FALSE),"0") -> 0 | BQ12: CENTRO DE PROCESAMIENTO | BR12: =_xlfn.IFNA(VLOOKUP(BQ12,$BN$3:$BO$44,2,FALSE),"0") -> 1 | BW12: =BT12 -> 0 | BX12: =BU12 -> 0
E13: NOVIEMBRE | F13: =_xlfn.IFNA(VLOOKUP(E13,$B$3:$C$14,2,FALSE),"0") -> 0 | AH13: NUEVA E.P.S. | AI13: =_xlfn.IFNA(VLOOKUP(AH13,$AE$3:$AF$17,2,FALSE),"0") -> 6 | AK13: Hernia inguinal unilateral o no especificada, sin obstruccion ni gangrena | AL13: 1 | AN13: Herida de dedo(s) de la mano, con dano de la(s) una(s) | AO13: =_xlfn.IFNA(VLOOKUP(AN13,$AK$3:$AL$7,2,FALSE),"0") -> 0 | AQ13: Fractura de otros huesos metacarpianos | AR13: 1 | AW13: Fiebre, no especificada | AX13: =_xlfn.IFNA(VLOOKUP(AW13,$AQ$4:$AS$328,2,FALSE),"0") -> 0 | AY13: =_xlfn.IFNA(VLOOKUP(AW13,$AQ$4:$AS$328,3,FALSE),"0") -> 0 | AZ13: =SUM(AX13:AY13) -> 0 | BE13: AUXILIAR DE COCINA | BF13: =_xlfn.IFNA(VLOOKUP(BE13,$BB$3:$BC$48,2,FALSE),"0") -> 1 | BQ13: CENTRO NIÑEZ | BR13: =_xlfn.IFNA(VLOOKUP(BQ13,$BN$3:$BO$44,2,FALSE),"0") -> 0 | BW13: =BT13 -> 0 | BX13: =BU13 -> 0
E14: DICIEMBRE | F14: =_xlfn.IFNA(VLOOKUP(E14,$B$3:$C$14,2,FALSE),"0") -> 0 | AH14: SALUD TOTAL | AI14: =_xlfn.IFNA(VLOOKUP(AH14,$AE$3:$AF$17,2,FALSE),"0") -> 3 | AK14: Fractura de hueso del metatarso | AL14: 1 | AN14: Herida de la muneca y de la mano, parte no especificada | AO14: =_xlfn.IFNA(VLOOKUP(AN14,$AK$3:$AL$7,2,FALSE),"0") -> 0 | AQ14: Hernia inguinal unilateral o no especificada, sin obstruccion ni gangrena | AS14: 1 | AW14: Herida de dedo(s) de la mano, con dano de la(s) una(s) | AX14: =_xlfn.IFNA(VLOOKUP(AW14,$AQ$4:$AS$328,2,FALSE),"0") -> 0 | AY14: =_xlfn.IFNA(VLOOKUP(AW14,$AQ$4:$AS$328,3,FALSE),"0") -> 0 | AZ14: =SUM(AX14:AY14) -> 0 | BE14: AUXILIAR DE PANADERIA | BF14: =_xlfn.IFNA(VLOOKUP(BE14,$BB$3:$BC$48,2,FALSE),"0") -> 0 | BQ14: CENTRO RECREACIONAL CLL 48 | BR14: =_xlfn.IFNA(VLOOKUP(BQ14,$BN$3:$BO$44,2,FALSE),"0") -> 4 | BW14: =BT14 -> 0 | BX14: =BU14 -> 0
E15: Total | F15: =SUM(F3:F14) -> 15 | AH15: SALUDVIDA E.P.S. | AI15: =_xlfn.IFNA(VLOOKUP(AH15,$AE$3:$AF$17,2,FALSE),"0") -> 0 | AK15: Contusion del hombro y del brazo | AL15: 1 | AN15: Herida de otras partes de la cabeza | AO15: =_xlfn.IFNA(VLOOKUP(AN15,$AK$3:$AL$7,2,FALSE),"0") -> 0 | AQ15: Fractura de hueso del metatarso | AR15: 1 | AW15: Herida de la muneca y de la mano, parte no especificada | AX15: =_xlfn.IFNA(VLOOKUP(AW15,$AQ$4:$AS$328,2,FALSE),"0") -> 0 | AY15: =_xlfn.IFNA(VLOOKUP(AW15,$AQ$4:$AS$328,3,FALSE),"0") -> 0 | AZ15: =SUM(AX15:AY15) -> 0 | BE15: AUXILIAR DE PRIMEROS AUXILIOS | BF15: =_xlfn.IFNA(VLOOKUP(BE15,$BB$3:$BC$48,2,FALSE),"0") -> 0 | BQ15: CENTRO RECREACIONAL TURIPANA | BR15: =_xlfn.IFNA(VLOOKUP(BQ15,$BN$3:$BO$44,2,FALSE),"0") -> 7 | BW15: =BT15 -> 0 | BX15: =BU15 -> 0
AH16: COLMENA | AI16: =_xlfn.IFNA(VLOOKUP(AH16,$AE$3:$AF$17,2,FALSE),"0") -> 0 | AK16: No especificado | AL16: 1 | AN16: Herida de otras partes de la muneca y de la mano | AO16: =_xlfn.IFNA(VLOOKUP(AN16,$AK$3:$AL$7,2,FALSE),"0") -> 0 | AQ16: Contusion del hombro y del brazo | AR16: 1 | AW16: Herida de otras partes de la cabeza | AX16: =_xlfn.IFNA(VLOOKUP(AW16,$AQ$4:$AS$328,2,FALSE),"0") -> 0 | AY16: =_xlfn.IFNA(VLOOKUP(AW16,$AQ$4:$AS$328,3,FALSE),"0") -> 0 | AZ16: =SUM(AX16:AY16) -> 0 | BE16: AUXILIAR DE SERVICIOS | BF16: =_xlfn.IFNA(VLOOKUP(BE16,$BB$3:$BC$48,2,FALSE),"0") -> 0 | BQ16: CLUB SOCIAL | BR16: =_xlfn.IFNA(VLOOKUP(BQ16,$BN$3:$BO$44,2,FALSE),"0") -> 0 | BW16: =BT16 -> 0 | BX16: =BU16 -> 0
AH17: EMPRESA | AI17: =_xlfn.IFNA(VLOOKUP(AH17,$AE$3:$AF$17,2,FALSE),"0") -> 0 | AK17: Fractura de la clavicula | AL17: 1 | AN17: Infarto agudo del miocardio, sin otra especificacion | AO17: =_xlfn.IFNA(VLOOKUP(AN17,$AK$3:$AL$7,2,FALSE),"0") -> 0 | AQ17: No especificado | AS17: 1 | AW17: Herida de otras partes de la muneca y de la mano | AX17: =_xlfn.IFNA(VLOOKUP(AW17,$AQ$4:$AS$328,2,FALSE),"0") -> 0 | AY17: =_xlfn.IFNA(VLOOKUP(AW17,$AQ$4:$AS$328,3,FALSE),"0") -> 0 | AZ17: =SUM(AX17:AY17) -> 0 | BE17: AUXILIAR DE SISTEMAS | BF17: =_xlfn.IFNA(VLOOKUP(BE17,$BB$3:$BC$48,2,FALSE),"0") -> 0 | BK17: Total | BL17: =SUM(BL3:BL16) -> 20 | BQ17: CONTRATO I.C.B.F | BR17: =_xlfn.IFNA(VLOOKUP(BQ17,$BN$3:$BO$44,2,FALSE),"0") -> 0 | BW17: =BT17 -> 0 | BX17: =BU17 -> 0
AI18: =_xlfn.IFNA(VLOOKUP(AH18,$AE$3:$AF$17,2,FALSE),"0") -> 0 | AK18: Urticaria alergica | AL18: 2 | AN18: Infeccion aguda de las vias respiratorias superiores, no especificada | AO18: =_xlfn.IFNA(VLOOKUP(AN18,$AK$3:$AL$7,2,FALSE),"0") -> 0 | AQ18: Fractura de la clavicula | AR18: 1 | AW18: Infarto agudo del miocardio, sin otra especificacion | AX18: =_xlfn.IFNA(VLOOKUP(AW18,$AQ$4:$AS$328,2,FALSE),"0") -> 0 | AY18: =_xlfn.IFNA(VLOOKUP(AW18,$AQ$4:$AS$328,3,FALSE),"0") -> 0 | AZ18: =SUM(AX18:AY18) -> 0 | BE18: AUXILIAR NOMINA | BF18: =_xlfn.IFNA(VLOOKUP(BE18,$BB$3:$BC$48,2,FALSE),"0") -> 0 | BQ18: CRU MERCADEO | BR18: =_xlfn.IFNA(VLOOKUP(BQ18,$BN$3:$BO$44,2,FALSE),"0") -> 0 | BW18: =BT18 -> 0 | BX18: =BU18 -> 0
AK19: Fractura de la diafisis de la tibia | AL19: 1 | AN19: Infeccion aguda no especificada de las vias respiratorias inferiores | AO19: =_xlfn.IFNA(VLOOKUP(AN19,$AK$3:$AL$7,2,FALSE),"0") -> 0 | AQ19: Urticaria alergica | AS19: 2 | AW19: Infeccion aguda de las vias respiratorias superiores, no especificada | AX19: =_xlfn.IFNA(VLOOKUP(AW19,$AQ$4:$AS$328,2,FALSE),"0") -> 0 | AY19: =_xlfn.IFNA(VLOOKUP(AW19,$AQ$4:$AS$328,3,FALSE),"0") -> 0 | AZ19: =SUM(AX19:AY19) -> 0 | BE19: AYUDANTE | BF19: =_xlfn.IFNA(VLOOKUP(BE19,$BB$3:$BC$48,2,FALSE),"0") -> 0 | BQ19: DIRECCION RECREACION | BR19: =_xlfn.IFNA(VLOOKUP(BQ19,$BN$3:$BO$44,2,FALSE),"0") -> 0 | BW19: =BT19 -> 0 | BX19: =BU19 -> 0
AN20: Infeccion de vias urinarias, sitio no especificado | AO20: =_xlfn.IFNA(VLOOKUP(AN20,$AK$3:$AL$7,2,FALSE),"0") -> 0 | AQ20: Fractura de la diafisis de la tibia | AR20: 1 | AW20: Infeccion aguda no especificada de las vias respiratorias inferiores | AX20: =_xlfn.IFNA(VLOOKUP(AW20,$AQ$4:$AS$328,2,FALSE),"0") -> 0 | AY20: =_xlfn.IFNA(VLOOKUP(AW20,$AQ$4:$AS$328,3,FALSE),"0") -> 0 | AZ20: =SUM(AX20:AY20) -> 0 | BE20: AYUDANTE COCINA | BF20: =_xlfn.IFNA(VLOOKUP(BE20,$BB$3:$BC$48,2,FALSE),"0") -> 6 | BQ20: DPTO DE CONSTRUCCION | BR20: =_xlfn.IFNA(VLOOKUP(BQ20,$BN$3:$BO$44,2,FALSE),"0") -> 0 | BW20: =BT20 -> 0 | BX20: =BU20 -> 0
AN21: Infeccion intestinal viral, sin otra especificacion | AO21: =_xlfn.IFNA(VLOOKUP(AN21,$AK$3:$AL$7,2,FALSE),"0") -> 0 | AW21: Infeccion de vias urinarias, sitio no especificado | AX21: =_xlfn.IFNA(VLOOKUP(AW21,$AQ$4:$AS$328,2,FALSE),"0") -> 0 | AY21: =_xlfn.IFNA(VLOOKUP(AW21,$AQ$4:$AS$328,3,FALSE),"0") -> 0 | AZ21: =SUM(AX21:AY21) -> 0 | BE21: AYUDANTE MANTENIMIENTO | BF21: =_xlfn.IFNA(VLOOKUP(BE21,$BB$3:$BC$48,2,FALSE),"0") -> 0 | BQ21: EDIFICIO TESTA ROSA | BR21: =_xlfn.IFNA(VLOOKUP(BQ21,$BN$3:$BO$44,2,FALSE),"0") -> 0 | BW21: =BT21 -> 0 | BX21: =BU21 -> 0
AN22: Infeccion viral, no especificada | AO22: =_xlfn.IFNA(VLOOKUP(AN22,$AK$3:$AL$7,2,FALSE),"0") -> 0 | AW22: Infeccion intestinal viral, sin otra especificacion | AX22: =_xlfn.IFNA(VLOOKUP(AW22,$AQ$4:$AS$328,2,FALSE),"0") -> 0 | AY22: =_xlfn.IFNA(VLOOKUP(AW22,$AQ$4:$AS$328,3,FALSE),"0") -> 0 | AZ22: =SUM(AX22:AY22) -> 0 | BE22: BARMAN | BF22: =_xlfn.IFNA(VLOOKUP(BE22,$BB$3:$BC$48,2,FALSE),"0") -> 0 | BQ22: MANTENIMIENTO TECNICO | BR22: =_xlfn.IFNA(VLOOKUP(BQ22,$BN$3:$BO$44,2,FALSE),"0") -> 0 | BW22: =BT22 -> 0 | BX22: =BU22 -> 0
AN23: Iridociclitis aguda y subaguda | AO23: =_xlfn.IFNA(VLOOKUP(AN23,$AK$3:$AL$7,2,FALSE),"0") -> 0 | AW23: Infeccion viral, no especificada | AX23: =_xlfn.IFNA(VLOOKUP(AW23,$AQ$4:$AS$328,2,FALSE),"0") -> 0 | AY23: =_xlfn.IFNA(VLOOKUP(AW23,$AQ$4:$AS$328,3,FALSE),"0") -> 0 | AZ23: =SUM(AX23:AY23) -> 0 | BE23: CAJERO(A) | BF23: =_xlfn.IFNA(VLOOKUP(BE23,$BB$3:$BC$48,2,FALSE),"0") -> 0 | BQ23: MARTHA L. YEPES | BR23: =_xlfn.IFNA(VLOOKUP(BQ23,$BN$3:$BO$44,2,FALSE),"0") -> 0 | BW23: =BT23 -> 0 | BX23: =BU23 -> 0
AN24: Laringofaringitis aguda | AO24: =_xlfn.IFNA(VLOOKUP(AN24,$AK$3:$AL$7,2,FALSE),"0") -> 0 | AW24: Iridociclitis aguda y subaguda | AX24: =_xlfn.IFNA(VLOOKUP(AW24,$AQ$4:$AS$328,2,FALSE),"0") -> 0 | AY24: =_xlfn.IFNA(VLOOKUP(AW24,$AQ$4:$AS$328,3,FALSE),"0") -> 0 | AZ24: =SUM(AX24:AY24) -> 0 | BE24: CHEF | BF24: =_xlfn.IFNA(VLOOKUP(BE24,$BB$3:$BC$48,2,FALSE),"0") -> 1 | BQ24: No Existe | BR24: =_xlfn.IFNA(VLOOKUP(BQ24,$BN$3:$BO$44,2,FALSE),"0") -> 0 | BW24: =BT24 -> 0 | BX24: =BU24 -> 0
AN25: Mareo y desvanecimiento | AO25: =_xlfn.IFNA(VLOOKUP(AN25,$AK$3:$AL$7,2,FALSE),"0") -> 0 | AW25: Laringofaringitis aguda | AX25: =_xlfn.IFNA(VLOOKUP(AW25,$AQ$4:$AS$328,2,FALSE),"0") -> 0 | AY25: =_xlfn.IFNA(VLOOKUP(AW25,$AQ$4:$AS$328,3,FALSE),"0") -> 0 | AZ25: =SUM(AX25:AY25) -> 0 | BE25: COCINERO 1 | BF25: =_xlfn.IFNA(VLOOKUP(BE25,$BB$3:$BC$48,2,FALSE),"0") -> 3 | BQ25: PLANEACION | BR25: =_xlfn.IFNA(VLOOKUP(BQ25,$BN$3:$BO$44,2,FALSE),"0") -> 0 | BW25: =BT25 -> 0 | BX25: =BU25 -> 0
AN26: Otras enteritis virales | AO26: =_xlfn.IFNA(VLOOKUP(AN26,$AK$3:$AL$7,2,FALSE),"0") -> 0 | AW26: Mareo y desvanecimiento | AX26: =_xlfn.IFNA(VLOOKUP(AW26,$AQ$4:$AS$328,2,FALSE),"0") -> 0 | AY26: =_xlfn.IFNA(VLOOKUP(AW26,$AQ$4:$AS$328,3,FALSE),"0") -> 0 | AZ26: =SUM(AX26:AY26) -> 0 | BE26: COLABORADOR | BF26: =_xlfn.IFNA(VLOOKUP(BE26,$BB$3:$BC$48,2,FALSE),"0") -> 0 | BQ26: PLASDIBAR LTDA | BR26: =_xlfn.IFNA(VLOOKUP(BQ26,$BN$3:$BO$44,2,FALSE),"0") -> 0 | BW26: =BT26 -> 0 | BX26: =BU26 -> 0
AN27: Otras infecciones agudas de sitios multiples de las vias respiratorias superiores | AO27: =_xlfn.IFNA(VLOOKUP(AN27,$AK$3:$AL$7,2,FALSE),"0") -> 0 | AW27: Otras enteritis virales | AX27: =_xlfn.IFNA(VLOOKUP(AW27,$AQ$4:$AS$328,2,FALSE),"0") -> 0 | AY27: =_xlfn.IFNA(VLOOKUP(AW27,$AQ$4:$AS$328,3,FALSE),"0") -> 0 | AZ27: =SUM(AX27:AY27) -> 0 | BE27: COORDINADOR | BF27: =_xlfn.IFNA(VLOOKUP(BE27,$BB$3:$BC$48,2,FALSE),"0") -> 0 | BQ27: PROGRAMAS RECREATIVOS | BR27: =_xlfn.IFNA(VLOOKUP(BQ27,$BN$3:$BO$44,2,FALSE),"0") -> 0 | BW27: =BT27 -> 0 | BX27: =BU27 -> 0
AN28: Otros tipos de neumotorax espontaneo | AO28: =_xlfn.IFNA(VLOOKUP(AN28,$AK$3:$AL$7,2,FALSE),"0") -> 0 | AW28: Otras infecciones agudas de sitios multiples de las vias respiratorias superiores | AX28: =_xlfn.IFNA(VLOOKUP(AW28,$AQ$4:$AS$328,2,FALSE),"0") -> 0 | AY28: =_xlfn.IFNA(VLOOKUP(AW28,$AQ$4:$AS$328,3,FALSE),"0") -> 0 | AZ28: =SUM(AX28:AY28) -> 0 | BE28: EMPACADOR | BF28: =_xlfn.IFNA(VLOOKUP(BE28,$BB$3:$BC$48,2,FALSE),"0") -> 0 | BQ28: PROMOCION Y COMUNICACIONES | BR28: =_xlfn.IFNA(VLOOKUP(BQ28,$BN$3:$BO$44,2,FALSE),"0") -> 0 | BW28: =BT28 -> 0 | BX28: =BU28 -> 0
AN29: Parto por cesarea de emergencia | AO29: =_xlfn.IFNA(VLOOKUP(AN29,$AK$3:$AL$7,2,FALSE),"0") -> 0 | AW29: Otros tipos de neumotorax espontaneo | AX29: =_xlfn.IFNA(VLOOKUP(AW29,$AQ$4:$AS$328,2,FALSE),"0") -> 0 | AY29: =_xlfn.IFNA(VLOOKUP(AW29,$AQ$4:$AS$328,3,FALSE),"0") -> 0 | AZ29: =SUM(AX29:AY29) -> 0 | BE29: INSTRUCTOR | BF29: =_xlfn.IFNA(VLOOKUP(BE29,$BB$3:$BC$48,2,FALSE),"0") -> 0 | BQ29: RECREACION Y TURISMO | BR29: =_xlfn.IFNA(VLOOKUP(BQ29,$BN$3:$BO$44,2,FALSE),"0") -> 0 | BW29: =BT29 -> 0 | BX29: =BU29 -> 0
AN30: Parto por cesarea, sin otra especificacion | AO30: =_xlfn.IFNA(VLOOKUP(AN30,$AK$3:$AL$7,2,FALSE),"0") -> 0 | AW30: Parto por cesarea de emergencia | AX30: =_xlfn.IFNA(VLOOKUP(AW30,$AQ$4:$AS$328,2,FALSE),"0") -> 0 | AY30: =_xlfn.IFNA(VLOOKUP(AW30,$AQ$4:$AS$328,3,FALSE),"0") -> 0 | AZ30: =SUM(AX30:AY30) -> 0 | BE30: MAITRE | BF30: =_xlfn.IFNA(VLOOKUP(BE30,$BB$3:$BC$48,2,FALSE),"0") -> 0 | BQ30: SALGARITO | BR30: =_xlfn.IFNA(VLOOKUP(BQ30,$BN$3:$BO$44,2,FALSE),"0") -> 0 | BW30: =BT30 -> 0 | BX30: =BU30 -> 0
AN31: Periodontitis cronica | AO31: =_xlfn.IFNA(VLOOKUP(AN31,$AK$3:$AL$7,2,FALSE),"0") -> 0 | AW31: Parto por cesarea, sin otra especificacion | AX31: =_xlfn.IFNA(VLOOKUP(AW31,$AQ$4:$AS$328,2,FALSE),"0") -> 0 | AY31: =_xlfn.IFNA(VLOOKUP(AW31,$AQ$4:$AS$328,3,FALSE),"0") -> 0 | AZ31: =SUM(AX31:AY31) -> 0 | BE31: MANIPULADOR DE ALIMENTOS | BF31: =_xlfn.IFNA(VLOOKUP(BE31,$BB$3:$BC$48,2,FALSE),"0") -> 0 | BQ31: SALGARITO MERCADEO | BR31: =_xlfn.IFNA(VLOOKUP(BQ31,$BN$3:$BO$44,2,FALSE),"0") -> 0 | BW31: =BT31 -> 0 | BX31: =BU31 -> 0
AN32: Pulpitis | AO32: =_xlfn.IFNA(VLOOKUP(AN32,$AK$3:$AL$7,2,FALSE),"0") -> 0 | AW32: Periodontitis cronica | AX32: =_xlfn.IFNA(VLOOKUP(AW32,$AQ$4:$AS$328,2,FALSE),"0") -> 0 | AY32: =_xlfn.IFNA(VLOOKUP(AW32,$AQ$4:$AS$328,3,FALSE),"0") -> 0 | AZ32: =SUM(AX32:AY32) -> 0 | BE32: MESERO | BF32: =_xlfn.IFNA(VLOOKUP(BE32,$BB$3:$BC$48,2,FALSE),"0") -> 0 | BQ32: SEDE CARIBE | BR32: =_xlfn.IFNA(VLOOKUP(BQ32,$BN$3:$BO$44,2,FALSE),"0") -> 1 | BW32: =BT32 -> 0 | BX32: =BU32 -> 0
... AN42: Lumbago no especificado | AO42: =_xlfn.IFNA(VLOOKUP(AN42,$AK$3:$AL$7,2,FALSE),"0") -> 0 | AW42: Diarrea y gastroenteritis de presunto origen infeccioso | AX42: =_xlfn.IFNA(VLOOKUP(AW42,$AQ$4:$AS$328,2,FALSE),"0") -> 0 | AY42: =_xlfn.IFNA(VLOOKUP(AW42,$AQ$4:$AS$328,3,FALSE),"0") -> 0 | AZ42: =SUM(AX42:AY42) -> 0 | BE42: SUPERNUMERARIO(A) | BF42: =_xlfn.IFNA(VLOOKUP(BE42,$BB$3:$BC$48,2,FALSE),"0") -> 6 | BQ42: TURIPANA | BR42: =_xlfn.IFNA(VLOOKUP(BQ42,$BN$3:$BO$44,2,FALSE),"0") -> 0 | BW42: =BT42 -> 0 | BX42: =BU42 -> 0
AN43: Nacido vivo, unico | AO43: =_xlfn.IFNA(VLOOKUP(AN43,$AK$3:$AL$7,2,FALSE),"0") -> 0 | AW43: Varices en otros sitios especificados | AX43: =_xlfn.IFNA(VLOOKUP(AW43,$AQ$4:$AS$328,2,FALSE),"0") -> 0 | AY43: =_xlfn.IFNA(VLOOKUP(AW43,$AQ$4:$AS$328,3,FALSE),"0") -> 0 | AZ43: =SUM(AX43:AY43) -> 0 | BQ43: TURIPANA MERCADEO | BR43: =_xlfn.IFNA(VLOOKUP(BQ43,$BN$3:$BO$44,2,FALSE),"0") -> 1 | BW43: =BT43 -> 0 | BX43: =BU43 -> 0
AN44: No especificado | AO44: =_xlfn.IFNA(VLOOKUP(AN44,$AK$3:$AL$7,2,FALSE),"0") -> 0 | AW44: Varicela sin complicaciones | AX44: =_xlfn.IFNA(VLOOKUP(AW44,$AQ$4:$AS$328,2,FALSE),"0") -> 0 | AY44: =_xlfn.IFNA(VLOOKUP(AW44,$AQ$4:$AS$328,3,FALSE),"0") -> 0 | AZ44: =SUM(AX44:AY44) -> 0 | BW44: =BT44 -> 0 | BX44: =BU44 -> 0
AN45: Bronquitis aguda debida a otros microorganismos especificados | AO45: =_xlfn.IFNA(VLOOKUP(AN45,$AK$3:$AL$7,2,FALSE),"0") -> 0 | AW45: Otros traumatismos especificados de la muneca y de la mano | AX45: =_xlfn.IFNA(VLOOKUP(AW45,$AQ$4:$AS$328,2,FALSE),"0") -> 0 | AY45: =_xlfn.IFNA(VLOOKUP(AW45,$AQ$4:$AS$328,3,FALSE),"0") -> 0 | AZ45: =SUM(AX45:AY45) -> 0 | BW45: =BT45 -> 0 | BX45: =BU45 -> 0
AN46: Anomalias de la posicion del diente | AO46: =_xlfn.IFNA(VLOOKUP(AN46,$AK$3:$AL$7,2,FALSE),"0") -> 0 | AW46: Cuidado posterior a la ortopedia, no especificado | AX46: =_xlfn.IFNA(VLOOKUP(AW46,$AQ$4:$AS$328,2,FALSE),"0") -> 0 | AY46: =_xlfn.IFNA(VLOOKUP(AW46,$AQ$4:$AS$328,3,FALSE),"0") -> 0 | AZ46: =SUM(AX46:AY46) -> 0 | BW46: =BT46 -> 0 | BX46: =BU46 -> 0
AN47: 0 | AO47: =_xlfn.IFNA(VLOOKUP(AN47,$AK$3:$AL$7,2,FALSE),"0") -> 0 | AW47: Otros dolores abdominales y los no especificados | AX47: =_xlfn.IFNA(VLOOKUP(AW47,$AQ$4:$AS$328,2,FALSE),"0") -> 0 | AY47: =_xlfn.IFNA(VLOOKUP(AW47,$AQ$4:$AS$328,3,FALSE),"0") -> 1 | AZ47: =SUM(AX47:AY47) -> 1 | BW47: =BT47 -> 0 | BX47: =BU47 -> 0
AN48: 0 | AO48: =_xlfn.IFNA(VLOOKUP(AN48,$AK$3:$AL$7,2,FALSE),"0") -> 0 | AW48: Bronconeumonia, no especificada | AX48: =_xlfn.IFNA(VLOOKUP(AW48,$AQ$4:$AS$328,2,FALSE),"0") -> 0 | AY48: =_xlfn.IFNA(VLOOKUP(AW48,$AQ$4:$AS$328,3,FALSE),"0") -> 0 | AZ48: =SUM(AX48:AY48) -> 0 | BW48: =BT48 -> 0 | BX48: =BU48 -> 0
AN49: 0 | AO49: =_xlfn.IFNA(VLOOKUP(AN49,$AK$3:$AL$7,2,FALSE),"0") -> 0 | AW49: Dolor agudo | AX49: =_xlfn.IFNA(VLOOKUP(AW49,$AQ$4:$AS$328,2,FALSE),"0") -> 0 | AY49: =_xlfn.IFNA(VLOOKUP(AW49,$AQ$4:$AS$328,3,FALSE),"0") -> 0 | AZ49: =SUM(AX49:AY49) -> 0 | BW49: =BT49 -> 0 | BX49: =BU49 -> 0
...

Sheet Tempoactiva 2024
E1: PROCESO DE GESTION INTEGRAL | Q1: CODIGO: GI-FO-076
E3: AUSENTISMO POR ARL Y EPS | Q3: REV. 02 ENERO 12 DEL 2023
A7: No | B7: EMPRESA | C7: NOMBRE | D7: CEDULA | E7: Columna1 | F7: CARGO | G7: EMPRESA USUARIA | H7: ÁREA O DPTO | I7: GENERO | J7: MES | K7: N° DIAS DE INCAPACIDAD | L7: CLASE DE INCAPACIDAD | M7: TIPO DE INCAPACIDAD | N7: ENTIDAD | O7: AÑO | P7: F. INICIO | Q7: F. FIN | R7: CODIGO | S7: DESCRIPCION | T7: > 10 Dias | U7: D. T. P. | V7: A. Inc. | W7: M. Inc. | X7: Concepto | Y7: Descripción
A8: 1 | B8: TEMPOACTIVA | C8: =_xlfn.XLOOKUP(D8,[1]!Data[CEDULA],[1]!Data[Nombre Completo],"No Existe",0,1) -> KARINA GREGORIA SALAS BROCHERO | D8: 1007096798 | E8: =IFERROR(_xlfn.NUMBERVALUE(Data[[#This Row],[CEDULA ]],",","."),_xlfn.NUMBERVALUE(Data[[#This Row],[CEDULA ]],".",",")) -> 1007096798 | F8: =_xlfn.XLOOKUP(E8,[1]!Data[CEDULA],[1]!Data[CARGO],"No Existe",0,1) -> SUPERNUMERARIO(A) | G8: =_xlfn.XLOOKUP(E8,[1]!Data[CEDULA],[1]!Data[EMPRESA DONDE PRESTA SERVICIO],"No Existe",0,1) -> COMFAMILIAR ATLANTICO | H8: =_xlfn.XLOOKUP(E8,[1]!Data[CEDULA],[1]!Data[UBICACIÓN],"No Existe",0,1) -> SEDE NORTE | I8: MUJER | J8: =UPPER(TEXT(Data[[#This Row],[F. INICIO]],"mmmm")) -> ABRIL | K8: 1 | L8: EPS | M8: LICENCIA DE MATERNIDAD | N8: =_xlfn.XLOOKUP(D8,[1]!Data[CEDULA],[1]!Data[EPS/SURA],"No Existe",0,1) -> E.P.S SANITAS | O8: =YEAR(Data[[#This Row],[F. INICIO]]) -> 2024 | P8: 45383 | Q8: 45017 | R8: O829 | S8: =IF(Data[[#This Row],[TIPO DE INCAPACIDAD]]="LICENCIA DE PATERNIDAD","Licencia de paternidad",IF(Data[[#This Row],[TIPO DE INCAPACIDAD]]="LICENCIA DE LUTO","Licencia de Luto",_xlfn.IFNA(VLOOKUP(R8,'CIE-10 PARA RIPS'!$A$6:B13176,2,0),"No especificado"))) -> Parto por cesarea, sin otra especificacion | T8: =IF(P8<>"", IF(P8>0, IF(P8<=DATE(YEAR(P8),MONTH(P8),DAY(P8)), IF(P8>=DATE(YEAR(P8),MONTH(P8),1), IF(K8>10, C8, IF(SUMIFS($K:$K, $C:$C, C8, $P:$P, ">="&DATE(YEAR(P8),MONTH(P8),1), $P:$P, "<="&EOMONTH(P8,0))>10, C8, "")), ""))), "") | U8: =IF(AND(P8<>"", P8>=DATE(YEAR(P8),MONTH(P8),1), SUMIFS($K:$K, $C:$C, C8, $P:$P, ">="&DATE(YEAR(P8),MONTH(P8),1), $P:$P, "<="&EOMONTH(P8,0))>10), K8, "") | V8: =IF(AND(P8<>"", P8>=DATE(YEAR(P8),MONTH(P8),1), SUMIFS($K:$K, $C:$C, C8, $P:$P, ">="&DATE(YEAR(P8),MONTH(P8),1), $P:$P, "<="&EOMONTH(P8,0))>10), YEAR(P8), "") | W8: =IF(AND(P8<>"", P8>=DATE(YEAR(P8),MONTH(P8),1), SUMIFS($K:$K, $C:$C, C8, $P:$P, ">="&DATE(YEAR(P8),MONTH(P8),1), $P:$P, "<="&EOMONTH(P8,0))>10), TEXT(P8, "MMMM"), "") | X8: {=IF(AND(P8<>"", P8>=DATE(YEAR(P8),MONTH(P8),1), SUMIFS($K:$K, $C:$C, C8, $P:$P, ">="&DATE(YEAR(P8),MONTH(P8),1), $P:$P, "<="&EOMONTH(P8,0))>10), _xlfn.TEXTJOIN(", ", TRUE, _xlfn._xlws.FILTER($R:$R, ($C:$C=C8) * ($P:$P>=DATE(YEAR(P8),MONTH(P8),1)) * ($P:$P<=EOMONTH(P8,0)))), "")} | Y8: {=IF(AND(P8<>"", P8>=DATE(YEAR(P8),MONTH(P8),1), SUMIFS($K:$K, $C:$C, C8, $P:$P, ">="&DATE(YEAR(P8),MONTH(P8),1), $P:$P, "<="&EOMONTH(P8,0))>10), _xlfn.TEXTJOIN(", ", TRUE, _xlfn._xlws.FILTER($S:$S, ($C:$C=C8) * ($P:$P>=DATE(YEAR(P8),MONTH(P8),1)) * ($P:$P<=EOMONTH(P8,0)))), "")}
A9: 2 | B9: TEMPOACTIVA | C9: =_xlfn.XLOOKUP(D9,[1]!Data[CEDULA],[1]!Data[Nombre Completo],"No Existe",0,1) -> HELIS MARI RAMIREZ PATIÑO | D9: 1140868628 | E9: =IFERROR(_xlfn.NUMBERVALUE(Data[[#This Row],[CEDULA ]],",","."),_xlfn.NUMBERVALUE(Data[[#This Row],[CEDULA ]],".",",")) -> 1140868628 | F9: =_xlfn.XLOOKUP(E9,[1]!Data[CEDULA],[1]!Data[CARGO],"No Existe",0,1) -> SUPERNUMERARIO(A) | G9: =_xlfn.XLOOKUP(E9,[1]!Data[CEDULA],[1]!Data[EMPRESA DONDE PRESTA SERVICIO],"No Existe",0,1) -> COMFAMILIAR ATLANTICO | H9: =_xlfn.XLOOKUP(E9,[1]!Data[CEDULA],[1]!Data[UBICACIÓN],"No Existe",0,1) -> SEDE NORTE | I9: MUJER | J9: =UPPER(TEXT(Data[[#This Row],[F. INICIO]],"mmmm")) -> ABRIL | K9: 3 | L9: EPS | M9: ENFERMENDAD GENERAL | N9: =_xlfn.XLOOKUP(D9,[1]!Data[CEDULA],[1]!Data[EPS/SURA],"No Existe",0,1) -> MUTUALSER | O9: =YEAR(Data[[#This Row],[F. INICIO]]) -> 2024 | P9: 45383 | Q9: 45354 | R9: Z359 | S9: =IF(Data[[#This Row],[TIPO DE INCAPACIDAD]]="LICENCIA DE PATERNIDAD","Licencia de paternidad",IF(Data[[#This Row],[TIPO DE INCAPACIDAD]]="LICENCIA DE LUTO","Licencia de Luto",_xlfn.IFNA(VLOOKUP(R9,'CIE-10 PARA RIPS'!$A$6:B13196,2,0),"No especificado"))) -> Supervision de embarazo de alto riesgo, sin otra especificacion | T9: =IF(P9<>"", IF(P9>0, IF(P9<=DATE(YEAR(P9),MONTH(P9),DAY(P9)), IF(P9>=DATE(YEAR(P9),MONTH(P9),1), IF(K9>10, C9, IF(SUMIFS($K:$K, $C:$C, C9, $P:$P, ">="&DATE(YEAR(P9),MONTH(P9),1), $P:$P, "<="&EOMONTH(P9,0))>10, C9, "")), ""))), "") -> HELIS MARI RAMIREZ PATIÑO | U9: =IF(AND(P9<>"", P9>=DATE(YEAR(P9),MONTH(P9),1), SUMIFS($K:$K, $C:$C, C9, $P:$P, ">="&DATE(YEAR(P9),MONTH(P9),1), $P:$P, "<="&EOMONTH(P9,0))>10), K9, "") -> 3 | V9: =IF(AND(P9<>"", P9>=DATE(YEAR(P9),MONTH(P9),1), SUMIFS($K:$K, $C:$C, C9, $P:$P, ">="&DATE(YEAR(P9),MONTH(P9),1), $P:$P, "<="&EOMONTH(P9,0))>10), YEAR(P9), "") -> 2024 | W9: =IF(AND(P9<>"", P9>=DATE(YEAR(P9),MONTH(P9),1), SUMIFS($K:$K, $C:$C, C9, $P:$P, ">="&DATE(YEAR(P9),MONTH(P9),1), $P:$P, "<="&EOMONTH(P9,0))>10), TEXT(P9, "MMMM"), "") -> abril | X9: {=IF(AND(P9<>"", P9>=DATE(YEAR(P9),MONTH(P9),1), SUMIFS($K:$K, $C:$C, C9, $P:$P, ">="&DATE(YEAR(P9),MONTH(P9),1), $P:$P, "<="&EOMONTH(P9,0))>10), _xlfn.TEXTJOIN(", ", TRUE, _xlfn._xlws.FILTER($R:$R, ($C:$C=C9) * ($P:$P>=DATE(YEAR(P9),MONTH(P9),1)) * ($P:$P<=EOMONTH(P9,0)))), "")} -> Z359, O821 | Y9: {=IF(AND(P9<>"", P9>=DATE(YEAR(P9),MONTH(P9),1), SUMIFS($K:$K, $C:$C, C9, $P:$P, ">="&DATE(YEAR(P9),MONTH(P9),1), $P:$P, "<="&EOMONTH(P9,0))>10), _xlfn.TEXTJOIN(", ", TRUE, _xlfn._xlws.FILTER($S:$S, ($C:$C=C9) * ($P:$P>=DATE(YEAR(P9),MONTH(P9),1)) * ($P:$P<=EOMONTH(P9,0)))), "")} -> Supervision de embarazo de alto riesgo, sin otra especificacion, Parto por cesarea de emergencia
A10: 3 | B10: TEMPOACTIVA | C10: =_xlfn.XLOOKUP(D10,[1]!Data[CEDULA],[1]!Data[Nombre Completo],"No Existe",0,1) -> HELIS MARI RAMIREZ PATIÑO | D10: 1140868628 | E10: =IFERROR(_xlfn.NUMBERVALUE(Data[[#This Row],[CEDULA ]],",","."),_xlfn.NUMBERVALUE(Data[[#This Row],[CEDULA ]],".",",")) -> 1140868628 | F10: =_xlfn.XLOOKUP(E10,[1]!Data[CEDULA],[1]!Data[CARGO],"No Existe",0,1) -> SUPERNUMERARIO(A) | G10: =_xlfn.XLOOKUP(E10,[1]!Data[CEDULA],[1]!Data[EMPRESA DONDE PRESTA SERVICIO],"No Existe",0,1) -> COMFAMILIAR ATLANTICO | H10: =_xlfn.XLOOKUP(E10,[1]!Data[CEDULA],[1]!Data[UBICACIÓN],"No Existe",0,1) -> SEDE NORTE | I10: MUJER | J10: =UPPER(TEXT(Data[[#This Row],[F. INICIO]],"mmmm")) -> ABRIL | K10: 20 | L10: EPS | M10: LICENCIA DE MATERNIDAD | N10: =_xlfn.XLOOKUP(D10,[1]!Data[CEDULA],[1]!Data[EPS/SURA],"No Existe",0,1) -> MUTUALSER | O10: =YEAR(Data[[#This Row],[F. INICIO]]) -> 2024 | P10: 45393 | Q10: 45412 | R10: O821 | S10: =IF(Data[[#This Row],[TIPO DE INCAPACIDAD]]="LICENCIA DE PATERNIDAD","Licencia de paternidad",IF(Data[[#This Row],[TIPO DE INCAPACIDAD]]="LICENCIA DE LUTO","Licencia de Luto",_xlfn.IFNA(VLOOKUP(R10,'CIE-10 PARA RIPS'!$A$6:B13232,2,0),"No especificado"))) -> Parto por cesarea de emergencia | T10: =IF(P10<>"", IF(P10>0, IF(P10<=DATE(YEAR(P10),MONTH(P10),DAY(P10)), IF(P10>=DATE(YEAR(P10),MONTH(P10),1), IF(K10>10, C10, IF(SUMIFS($K:$K, $C:$C, C10, $P:$P, ">="&DATE(YEAR(P10),MONTH(P10),1), $P:$P, "<="&EOMONTH(P10,0))>10, C10, "")), ""))), "") -> HELIS MARI RAMIREZ PATIÑO | U10: =IF(AND(P10<>"", P10>=DATE(YEAR(P10),MONTH(P10),1), SUMIFS($K:$K, $C:$C, C10, $P:$P, ">="&DATE(YEAR(P10),MONTH(P10),1), $P:$P, "<="&EOMONTH(P10,0))>10), K10, "") -> 20 | V10: =IF(AND(P10<>"", P10>=DATE(YEAR(P10),MONTH(P10),1), SUMIFS($K:$K, $C:$C, C10, $P:$P, ">="&DATE(YEAR(P10),MONTH(P10),1), $P:$P, "<="&EOMONTH(P10,0))>10), YEAR(P10), "") -> 2024 | W10: =IF(AND(P10<>"", P10>=DATE(YEAR(P10),MONTH(P10),1), SUMIFS($K:$K, $C:$C, C10, $P:$P, ">="&DATE(YEAR(P10),MONTH(P10),1), $P:$P, "<="&EOMONTH(P10,0))>10), TEXT(P10, "MMMM"), "") -> abril | X10: {=IF(AND(P10<>"", P10>=DATE(YEAR(P10),MONTH(P10),1), SUMIFS($K:$K, $C:$C, C10, $P:$P, ">="&DATE(YEAR(P10),MONTH(P10),1), $P:$P, "<="&EOMONTH(P10,0))>10), _xlfn.TEXTJOIN(", ", TRUE, _xlfn._xlws.FILTER($R:$R, ($C:$C=C10) * ($P:$P>=DATE(YEAR(P10),MONTH(P10),1)) * ($P:$P<=EOMONTH(P10,0)))), "")} -> Z359, O821 | Y10: {=IF(AND(P10<>"", P10>=DATE(YEAR(P10),MONTH(P10),1), SUMIFS($K:$K, $C:$C, C10, $P:$P, ">="&DATE(YEAR(P10),MONTH(P10),1), $P:$P, "<="&EOMONTH(P10,0))>10), _xlfn.TEXTJOIN(", ", TRUE, _xlfn._xlws.FILTER($S:$S, ($C:$C=C10) * ($P:$P>=DATE(YEAR(P10),MONTH(P10),1)) * ($P:$P<=EOMONTH(P10,0)))), "")} -> Supervision de embarazo de alto riesgo, sin otra especificacion, Parto por cesarea de emergencia
A11: 4 | B11: TEMPOACTIVA | C11: =_xlfn.XLOOKUP(D11,[1]!Data[CEDULA],[1]!Data[Nombre Completo],"No Existe",0,1) -> HELIS MARI RAMIREZ PATIÑO | D11: 1140868628 | E11: =IFERROR(_xlfn.NUMBERVALUE(Data[[#This Row],[CEDULA ]],",","."),_xlfn.NUMBERVALUE(Data[[#This Row],[CEDULA ]],".",",")) -> 1140868628 | F11: =_xlfn.XLOOKUP(E11,[1]!Data[CEDULA],[1]!Data[CARGO],"No Existe",0,1) -> SUPERNUMERARIO(A) | G11: =_xlfn.XLOOKUP(E11,[1]!Data[CEDULA],[1]!Data[EMPRESA DONDE PRESTA SERVICIO],"No Existe",0,1) -> COMFAMILIAR ATLANTICO | H11: =_xlfn.XLOOKUP(E11,[1]!Data[CEDULA],[1]!Data[UBICACIÓN],"No Existe",0,1) -> SEDE NORTE | I11: MUJER | J11: =UPPER(TEXT(Data[[#This Row],[F. INICIO]],"mmmm")) -> AGOSTO | K11: 31 | L11: EPS | M11: LICENCIA DE MATERNIDAD | N11: =_xlfn.XLOOKUP(D11,[1]!Data[CEDULA],[1]!Data[EPS/SURA],"No Existe",0,1) -> MUTUALSER | O11: =YEAR(Data[[#This Row],[F. INICIO]]) -> 2024 | P11: 45505 | Q11: 45535 | R11: O821 | S11: =IF(Data[[#This Row],[TIPO DE INCAPACIDAD]]="LICENCIA DE PATERNIDAD","Licencia de paternidad",IF(Data[[#This Row],[TIPO DE INCAPACIDAD]]="LICENCIA DE LUTO","Licencia de Luto",_xlfn.IFNA(VLOOKUP(R11,'CIE-10 PARA RIPS'!$A$6:B13236,2,0),"No especificado"))) -> Parto por cesarea de emergencia | T11: =IF(P11<>"", IF(P11>0, IF(P11<=DATE(YEAR(P11),MONTH(P11),DAY(P11)), IF(P11>=DATE(YEAR(P11),MONTH(P11),1), IF(K11>10, C11, IF(SUMIFS($K:$K, $C:$C, C11, $P:$P, ">="&DATE(YEAR(P11),MONTH(P11),1), $P:$P, "<="&EOMONTH(P11,0))>10, C11, "")), ""))), "") -> HELIS MARI RAMIREZ PATIÑO | U11: =IF(AND(P11<>"", P11>=DATE(YEAR(P11),MONTH(P11),1), SUMIFS($K:$K, $C:$C, C11, $P:$P, ">="&DATE(YEAR(P11),MONTH(P11),1), $P:$P, "<="&EOMONTH(P11,0))>10), K11, "") -> 31 | V11: =IF(AND(P11<>"", P11>=DATE(YEAR(P11),MONTH(P11),1), SUMIFS($K:$K, $C:$C, C11, $P:$P, ">="&DATE(YEAR(P11),MONTH(P11),1), $P:$P, "<="&EOMONTH(P11,0))>10), YEAR(P11), "") -> 2024 | W11: =IF(AND(P11<>"", P11>=DATE(YEAR(P11),MONTH(P11),1), SUMIFS($K:$K, $C:$C, C11, $P:$P, ">="&DATE(YEAR(P11),MONTH(P11),1), $P:$P, "<="&EOMONTH(P11,0))>10), TEXT(P11, "MMMM"), "") -> agosto | X11: {=IF(AND(P11<>"", P11>=DATE(YEAR(P11),MONTH(P11),1), SUMIFS($K:$K, $C:$C, C11, $P:$P, ">="&DATE(YEAR(P11),MONTH(P11),1), $P:$P, "<="&EOMONTH(P11,0))>10), _xlfn.TEXTJOIN(", ", TRUE, _xlfn._xlws.FILTER($R:$R, ($C:$C=C11) * ($P:$P>=DATE(YEAR(P11),MONTH(P11),1)) * ($P:$P<=EOMONTH(P11,0)))), "")} -> O821 | Y11: {=IF(AND(P11<>"", P11>=DATE(YEAR(P11),MONTH(P11),1), SUMIFS($K:$K, $C:$C, C11, $P:$P, ">="&DATE(YEAR(P11),MONTH(P11),1), $P:$P, "<="&EOMONTH(P11,0))>10), _xlfn.TEXTJOIN(", ", TRUE, _xlfn._xlws.FILTER($S:$S, ($C:$C=C11) * ($P:$P>=DATE(YEAR(P11),MONTH(P11),1)) * ($P:$P<=EOMONTH(P11,0)))), "")} -> Parto por cesarea de emergencia
A12: 5 | B12: TEMPOACTIVA | C12: =_xlfn.XLOOKUP(D12,[1]!Data[CEDULA],[1]!Data[Nombre Completo],"No Existe",0,1) -> KARINA GREGORIA SALAS BROCHERO | D12: 1007096798 | E12: =IFERROR(_xlfn.NUMBERVALUE(Data[[#This Row],[CEDULA ]],",","."),_xlfn.NUMBERVALUE(Data[[#This Row],[CEDULA ]],".",",")) -> 1007096798 | F12: =_xlfn.XLOOKUP(E12,[1]!Data[CEDULA],[1]!Data[CARGO],"No Existe",0,1) -> SUPERNUMERARIO(A) | G12: =_xlfn.XLOOKUP(E12,[1]!Data[CEDULA],[1]!Data[EMPRESA DONDE PRESTA SERVICIO],"No Existe",0,1) -> COMFAMILIAR ATLANTICO | H12: =_xlfn.XLOOKUP(E12,[1]!Data[CEDULA],[1]!Data[UBICACIÓN],"No Existe",0,1) -> SEDE NORTE | I12: MUJER | J12: =UPPER(TEXT(Data[[#This Row],[F. INICIO]],"mmmm")) -> ENERO | K12: 31 | L12: EPS | M12: LICENCIA DE MATERNIDAD | N12: =_xlfn.XLOOKUP(D12,[1]!Data[CEDULA],[1]!Data[EPS/SURA],"No Existe",0,1) -> E.P.S SANITAS | O12: =YEAR(Data[[#This Row],[F. INICIO]]) -> 2024 | P12: 45292 | Q12: 45322 | R12: O829 | S12: =IF(Data[[#This Row],[TIPO DE INCAPACIDAD]]="LICENCIA DE PATERNIDAD","Licencia de paternidad",IF(Data[[#This Row],[TIPO DE INCAPACIDAD]]="LICENCIA DE LUTO","Licencia de Luto",_xlfn.IFNA(VLOOKUP(R12,'CIE-10 PARA RIPS'!$A$6:B13173,2,0),"No especificado"))) -> Parto por cesarea, sin otra especificacion | T12: =IF(P12<>"", IF(P12>0, IF(P12<=DATE(YEAR(P12),MONTH(P12),DAY(P12)), IF(P12>=DATE(YEAR(P12),MONTH(P12),1), IF(K12>10, C12, IF(SUMIFS($K:$K, $C:$C, C12, $P:$P, ">="&DATE(YEAR(P12),MONTH(P12),1), $P:$P, "<="&EOMONTH(P12,0))>10, C12, "")), ""))), "") -> KARINA GREGORIA SALAS BROCHERO | U12: =IF(AND(P12<>"", P12>=DATE(YEAR(P12),MONTH(P12),1), SUMIFS($K:$K, $C:$C, C12, $P:$P, ">="&DATE(YEAR(P12),MONTH(P12),1), $P:$P, "<="&EOMONTH(P12,0))>10), K12, "") -> 31 | V12: =IF(AND(P12<>"", P12>=DATE(YEAR(P12),MONTH(P12),1), SUMIFS($K:$K, $C:$C, C12, $P:$P, ">="&DATE(YEAR(P12),MONTH(P12),1), $P:$P, "<="&EOMONTH(P12,0))>10), YEAR(P12), "") -> 2024 | W12: =IF(AND(P12<>"", P12>=DATE(YEAR(P12),MONTH(P12),1), SUMIFS($K:$K, $C:$C, C12, $P:$P, ">="&DATE(YEAR(P12),MONTH(P12),1), $P:$P, "<="&EOMONTH(P12,0))>10), TEXT(P12, "MMMM"), "") -> enero | X12: {=IF(AND(P12<>"", P12>=DATE(YEAR(P12),MONTH(P12),1), SUMIFS($K:$K, $C:$C, C12, $P:$P, ">="&DATE(YEAR(P12),MONTH(P12),1), $P:$P, "<="&EOMONTH(P12,0))>10), _xlfn.TEXTJOIN(", ", TRUE, _xlfn._xlws.FILTER($R:$R, ($C:$C=C12) * ($P:$P>=DATE(YEAR(P12),MONTH(P12),1)) * ($P:$P<=EOMONTH(P12,0)))), "")} -> O829 | Y12: {=IF(AND(P12<>"", P12>=DATE(YEAR(P12),MONTH(P12),1), SUMIFS($K:$K, $C:$C, C12, $P:$P, ">="&DATE(YEAR(P12),MONTH(P12),1), $P:$P, "<="&EOMONTH(P12,0))>10), _xlfn.TEXTJOIN(", ", TRUE, _xlfn._xlws.FILTER($S:$S, ($C:$C=C12) * ($P:$P>=DATE(YEAR(P12),MONTH(P12),1)) * ($P:$P<=EOMONTH(P12,0)))), "")} -> Parto por cesarea, sin otra especificacion
A13: 6 | B13: TEMPOACTIVA | C13: =_xlfn.XLOOKUP(D13,[1]!Data[CEDULA],[1]!Data[Nombre Completo],"No Existe",0,1) -> GENISIS MARIA CANTILLO TORRES | D13: 1002228922 | E13: =IFERROR(_xlfn.NUMBERVALUE(Data[[#This Row],[CEDULA ]],",","."),_xlfn.NUMBERVALUE(Data[[#This Row],[CEDULA ]],".",",")) -> 1002228922 | F13: =_xlfn.XLOOKUP(E13,[1]!Data[CEDULA],[1]!Data[CARGO],"No Existe",0,1) -> MESERO | G13: =_xlfn.XLOOKUP(E13,[1]!Data[CEDULA],[1]!Data[EMPRESA DONDE PRESTA SERVICIO],"No Existe",0,1) -> COMFAMILIAR ATLANTICO | H13: =_xlfn.XLOOKUP(E13,[1]!Data[CEDULA],[1]!Data[UBICACIÓN],"No Existe",0,1) -> SEDE SPORT GYM | I13: MUJER | J13: =UPPER(TEXT(Data[[#This Row],[F. INICIO]],"mmmm")) -> ENERO | K13: 31 | L13: EPS | M13: LICENCIA DE MATERNIDAD | N13: =_xlfn.XLOOKUP(D13,[1]!Data[CEDULA],[1]!Data[EPS/SURA],"No Existe",0,1) -> MUTUALSER | O13: =YEAR(Data[[#This Row],[F. INICIO]]) -> 2024 | P13: 45292 | Q13: 45322 | R13: O829 | S13: =IF(Data[[#This Row],[TIPO DE INCAPACIDAD]]="LICENCIA DE PATERNIDAD","Licencia de paternidad",IF(Data[[#This Row],[TIPO DE INCAPACIDAD]]="LICENCIA DE LUTO","Licencia de Luto",_xlfn.IFNA(VLOOKUP(R13,'CIE-10 PARA RIPS'!$A$6:B13177,2,0),"No especificado"))) -> Parto por cesarea, sin otra especificacion | T13: =IF(P13<>"", IF(P13>0, IF(P13<=DATE(YEAR(P13),MONTH(P13),DAY(P13)), IF(P13>=DATE(YEAR(P13),MONTH(P13),1), IF(K13>10, C13, IF(SUMIFS($K:$K, $C:$C, C13, $P:$P, ">="&DATE(YEAR(P13),MONTH(P13),1), $P:$P, "<="&EOMONTH(P13,0))>10, C13, "")), ""))), "") -> GENISIS MARIA CANTILLO TORRES | U13: =IF(AND(P13<>"", P13>=DATE(YEAR(P13),MONTH(P13),1), SUMIFS($K:$K, $C:$C, C13, $P:$P, ">="&DATE(YEAR(P13),MONTH(P13),1), $P:$P, "<="&EOMONTH(P13,0))>10), K13, "") -> 31 | V13: =IF(AND(P13<>"", P13>=DATE(YEAR(P13),MONTH(P13),1), SUMIFS($K:$K, $C:$C, C13, $P:$P, ">="&DATE(YEAR(P13),MONTH(P13),1), $P:$P, "<="&EOMONTH(P13,0))>10), YEAR(P13), "") -> 2024 | W13: =IF(AND(P13<>"", P13>=DATE(YEAR(P13),MONTH(P13),1), SUMIFS($K:$K, $C:$C, C13, $P:$P, ">="&DATE(YEAR(P13),MONTH(P13),1), $P:$P, "<="&EOMONTH(P13,0))>10), TEXT(P13, "MMMM"), "") -> enero | X13: {=IF(AND(P13<>"", P13>=DATE(YEAR(P13),MONTH(P13),1), SUMIFS($K:$K, $C:$C, C13, $P:$P, ">="&DATE(YEAR(P13),MONTH(P13),1), $P:$P, "<="&EOMONTH(P13,0))>10), _xlfn.TEXTJOIN(", ", TRUE, _xlfn._xlws.FILTER($R:$R, ($C:$C=C13) * ($P:$P>=DATE(YEAR(P13),MONTH(P13),1)) * ($P:$P<=EOMONTH(P13,0)))), "")} -> O829 | Y13: {=IF(AND(P13<>"", P13>=DATE(YEAR(P13),MONTH(P13),1), SUMIFS($K:$K, $C:$C, C13, $P:$P, ">="&DATE(YEAR(P13),MONTH(P13),1), $P:$P, "<="&EOMONTH(P13,0))>10), _xlfn.TEXTJOIN(", ", TRUE, _xlfn._xlws.FILTER($S:$S, ($C:$C=C13) * ($P:$P>=DATE(YEAR(P13),MONTH(P13),1)) * ($P:$P<=EOMONTH(P13,0)))), "")} -> Parto por cesarea, sin otra especificacion
A14: 7 | B14: TEMPOACTIVA | C14: =_xlfn.XLOOKUP(D14,[1]!Data[CEDULA],[1]!Data[Nombre Completo],"No Existe",0,1) -> JUAN CARLOS CORRO MOLINA | D14: 1044392407 | E14: =IFERROR(_xlfn.NUMBERVALUE(Data[[#This Row],[CEDULA ]],",","."),_xlfn.NUMBERVALUE(Data[[#This Row],[CEDULA ]],".",",")) -> 1044392407 | F14: =_xlfn.XLOOKUP(E14,[1]!Data[CEDULA],[1]!Data[CARGO],"No Existe",0,1) -> SUPERNUMERARIO(A) | G14: =_xlfn.XLOOKUP(E14,[1]!Data[CEDULA],[1]!Data[EMPRESA DONDE PRESTA SERVICIO],"No Existe",0,1) -> COMFAMILIAR ATLANTICO | H14: =_xlfn.XLOOKUP(E14,[1]!Data[CEDULA],[1]!Data[UBICACIÓN],"No Existe",0,1) -> CENTRO RECREACIONAL TURIPANA | I14: HOMBRE | J14: =UPPER(TEXT(Data[[#This Row],[F. INICIO]],"mmmm")) -> ENERO | K14: 6 | L14: EPS | M14: ENFERMENDAD GENERAL | N14: =_xlfn.XLOOKUP(D14,[1]!Data[CEDULA],[1]!Data[EPS/SURA],"No Existe",0,1) -> MUTUALSER | O14: =YEAR(Data[[#This Row],[F. INICIO]]) -> 2024 | P14: 45292 | Q14: 45297 | R14: S835 | S14: =IF(Data[[#This Row],[TIPO DE INCAPACIDAD]]="LICENCIA DE PATERNIDAD","Licencia de paternidad",IF(Data[[#This Row],[TIPO DE INCAPACIDAD]]="LICENCIA DE LUTO","Licencia de Luto",_xlfn.IFNA(VLOOKUP(R14,'CIE-10 PARA RIPS'!$A$6:B13180,2,0),"No especificado"))) -> Esguinces y torceduras que comprometen el ligamento cruzado (anterior) (posterior) de la rodilla | T14: =IF(P14<>"", IF(P14>0, IF(P14<=DATE(YEAR(P14),MONTH(P14),DAY(P14)), IF(P14>=DATE(YEAR(P14),MONTH(P14),1), IF(K14>10, C14, IF(SUMIFS($K:$K, $C:$C, C14, $P:$P, ">="&DATE(YEAR(P14),MONTH(P14),1), $P:$P, "<="&EOMONTH(P14,0))>10, C14, "")), ""))), "") | U14: =IF(AND(P14<>"", P14>=DATE(YEAR(P14),MONTH(P14),1), SUMIFS($K:$K, $C:$C, C14, $P:$P, ">="&DATE(YEAR(P14),MONTH(P14),1), $P:$P, "<="&EOMONTH(P14,0))>10), K14, "") | V14: =IF(AND(P14<>"", P14>=DATE(YEAR(P14),MONTH(P14),1), SUMIFS($K:$K, $C:$C, C14, $P:$P, ">="&DATE(YEAR(P14),MONTH(P14),1), $P:$P, "<="&EOMONTH(P14,0))>10), YEAR(P14), "") | W14: =IF(AND(P14<>"", P14>=DATE(YEAR(P14),MONTH(P14),1), SUMIFS($K:$K, $C:$C, C14, $P:$P, ">="&DATE(YEAR(P14),MONTH(P14),1), $P:$P, "<="&EOMONTH(P14,0))>10), TEXT(P14, "MMMM"), "") | X14: {=IF(AND(P14<>"", P14>=DATE(YEAR(P14),MONTH(P14),1), SUMIFS($K:$K, $C:$C, C14, $P:$P, ">="&DATE(YEAR(P14),MONTH(P14),1), $P:$P, "<="&EOMONTH(P14,0))>10), _xlfn.TEXTJOIN(", ", TRUE, _xlfn._xlws.FILTER($R:$R, ($C:$C=C14) * ($P:$P>=DATE(YEAR(P14),MONTH(P14),1)) * ($P:$P<=EOMONTH(P14,0)))), "")} | Y14: {=IF(AND(P14<>"", P14>=DATE(YEAR(P14),MONTH(P14),1), SUMIFS($K:$K, $C:$C, C14, $P:$P, ">="&DATE(YEAR(P14),MONTH(P14),1), $P:$P, "<="&EOMONTH(P14,0))>10), _xlfn.TEXTJOIN(", ", TRUE, _xlfn._xlws.FILTER($S:$S, ($C:$C=C14) * ($P:$P>=DATE(YEAR(P14),MONTH(P14),1)) * ($P:$P<=EOMONTH(P14,0)))), "")}
A15: 8 | B15: TEMPOACTIVA | C15: =_xlfn.XLOOKUP(D15,[1]!Data[CEDULA],[1]!Data[Nombre Completo],"No Existe",0,1) -> MARIA DEL CARMEN FERRER ALVIS | D15: 22506589 | E15: =IFERROR(_xlfn.NUMBERVALUE(Data[[#This Row],[CEDULA ]],",","."),_xlfn.NUMBERVALUE(Data[[#This Row],[CEDULA ]],".",",")) -> 22506589 | F15: =_xlfn.XLOOKUP(E15,[1]!Data[CEDULA],[1]!Data[CARGO],"No Existe",0,1) -> PORCINADOR | G15: =_xlfn.XLOOKUP(E15,[1]!Data[CEDULA],[1]!Data[EMPRESA DONDE PRESTA SERVICIO],"No Existe",0,1) -> COMFAMILIAR ATLANTICO | H15: =_xlfn.XLOOKUP(E15,[1]!Data[CEDULA],[1]!Data[UBICACIÓN],"No Existe",0,1) -> CENTRO DE PROCESAMIENTO | I15: MUJER | J15: =UPPER(TEXT(Data[[#This Row],[F. INICIO]],"mmmm")) -> ENERO | K15: 1 | L15: EPS | M15: ENFERMENDAD GENERAL | N15: =_xlfn.XLOOKUP(D15,[1]!Data[CEDULA],[1]!Data[EPS/SURA],"No Existe",0,1) -> SALUD TOTAL | O15: =YEAR(Data[[#This Row],[F. INICIO]]) -> 2024 | P15: 45300 | Q15: 45300 | R15: R51X | S15: =IF(Data[[#This Row],[TIPO DE INCAPACIDAD]]="LICENCIA DE PATERNIDAD","Licencia de paternidad",IF(Data[[#This Row],[TIPO DE INCAPACIDAD]]="LICENCIA DE LUTO","Licencia de Luto",_xlfn.IFNA(VLOOKUP(R15,'CIE-10 PARA RIPS'!$A$6:B13181,2,0),"No especificado"))) -> Cefalea | T15: =IF(P15<>"", IF(P15>0, IF(P15<=DATE(YEAR(P15),MONTH(P15),DAY(P15)), IF(P15>=DATE(YEAR(P15),MONTH(P15),1), IF(K15>10, C15, IF(SUMIFS($K:$K, $C:$C, C15, $P:$P, ">="&DATE(YEAR(P15),MONTH(P15),1), $P:$P, "<="&EOMONTH(P15,0))>10, C15, "")), ""))), "") | U15: =IF(AND(P15<>"", P15>=DATE(YEAR(P15),MONTH(P15),1), SUMIFS($K:$K, $C:$C, C15, $P:$P, ">="&DATE(YEAR(P15),MONTH(P15),1), $P:$P, "<="&EOMONTH(P15,0))>10), K15, "") | V15: =IF(AND(P15<>"", P15>=DATE(YEAR(P15),MONTH(P15),1), SUMIFS($K:$K, $C:$C, C15, $P:$P, ">="&DATE(YEAR(P15),MONTH(P15),1), $P:$P, "<="&EOMONTH(P15,0))>10), YEAR(P15), "") | W15: =IF(AND(P15<>"", P15>=DATE(YEAR(P15),MONTH(P15),1), SUMIFS($K:$K, $C:$C, C15, $P:$P, ">="&DATE(YEAR(P15),MONTH(P15),1), $P:$P, "<="&EOMONTH(P15,0))>10), TEXT(P15, "MMMM"), "") | X15: {=IF(AND(P15<>"", P15>=DATE(YEAR(P15),MONTH(P15),1), SUMIFS($K:$K, $C:$C, C15, $P:$P, ">="&DATE(YEAR(P15),MONTH(P15),1), $P:$P, "<="&EOMONTH(P15,0))>10), _xlfn.TEXTJOIN(", ", TRUE, _xlfn._xlws.FILTER($R:$R, ($C:$C=C15) * ($P:$P>=DATE(YEAR(P15),MONTH(P15),1)) * ($P:$P<=EOMONTH(P15,0)))), "")} | Y15: {=IF(AND(P15<>"", P15>=DATE(YEAR(P15),MONTH(P15),1), SUMIFS($K:$K, $C:$C, C15, $P:$P, ">="&DATE(YEAR(P15),MONTH(P15),1), $P:$P, "<="&EOMONTH(P15,0))>10), _xlfn.TEXTJOIN(", ", TRUE, _xlfn._xlws.FILTER($S:$S, ($C:$C=C15) * ($P:$P>=DATE(YEAR(P15),MONTH(P15),1)) * ($P:$P<=EOMONTH(P15,0)))), "")}
A16: 9 | B16: TEMPOACTIVA | C16: =_xlfn.XLOOKUP(D16,[1]!Data[CEDULA],[1]!Data[Nombre Completo],"No Existe",0,1) -> JHON JARLIS PABUENA EVERTSZ | D16: 72235252 | E16: =IFERROR(_xlfn.NUMBERVALUE(Data[[#This Row],[CEDULA ]],",","."),_xlfn.NUMBERVALUE(Data[[#This Row],[CEDULA ]],".",",")) -> 72235252 | F16: =_xlfn.XLOOKUP(E16,[1]!Data[CEDULA],[1]!Data[CARGO],"No Existe",0,1) -> MESERO | G16: =_xlfn.XLOOKUP(E16,[1]!Data[CEDULA],[1]!Data[EMPRESA DONDE PRESTA SERVICIO],"No Existe",0,1) -> COMFAMILIAR ATLANTICO | H16: =_xlfn.XLOOKUP(E16,[1]!Data[CEDULA],[1]!Data[UBICACIÓN],"No Existe",0,1) -> CENTRO RECREACIONAL CLL 48 | I16: HOMBRE | J16: =UPPER(TEXT(Data[[#This Row],[F. INICIO]],"mmmm")) -> ENERO | K16: 1 | L16: EPS | M16: ENFERMENDAD GENERAL | N16: =_xlfn.XLOOKUP(D16,[1]!Data[CEDULA],[1]!Data[EPS/SURA],"No Existe",0,1) -> EPS/SURA | O16: =YEAR(Data[[#This Row],[F. INICIO]]) -> 2024 | P16: 45296 | Q16: 45296 | R16: N390 | S16: =IF(Data[[#This Row],[TIPO DE INCAPACIDAD]]="LICENCIA DE PATERNIDAD","Licencia de paternidad",IF(Data[[#This Row],[TIPO DE INCAPACIDAD]]="LICENCIA DE LUTO","Licencia de Luto",_xlfn.IFNA(VLOOKUP(R16,'CIE-10 PARA RIPS'!$A$6:B13182,2,0),"No especificado"))) -> Infeccion de vias urinarias, sitio no especificado | T16: =IF(P16<>"", IF(P16>0, IF(P16<=DATE(YEAR(P16),MONTH(P16),DAY(P16)), IF(P16>=DATE(YEAR(P16),MONTH(P16),1), IF(K16>10, C16, IF(SUMIFS($K:$K, $C:$C, C16, $P:$P, ">="&DATE(YEAR(P16),MONTH(P16),1), $P:$P, "<="&EOMONTH(P16,0))>10, C16, "")), ""))), "") | U16: =IF(AND(P16<>"", P16>=DATE(YEAR(P16),MONTH(P16),1), SUMIFS($K:$K, $C:$C, C16, $P:$P, ">="&DATE(YEAR(P16),MONTH(P16),1), $P:$P, "<="&EOMONTH(P16,0))>10), K16, "") | V16: =IF(AND(P16<>"", P16>=DATE(YEAR(P16),MONTH(P16),1), SUMIFS($K:$K, $C:$C, C16, $P:$P, ">="&DATE(YEAR(P16),MONTH(P16),1), $P:$P, "<="&EOMONTH(P16,0))>10), YEAR(P16), "") | W16: =IF(AND(P16<>"", P16>=DATE(YEAR(P16),MONTH(P16),1), SUMIFS($K:$K, $C:$C, C16, $P:$P, ">="&DATE(YEAR(P16),MONTH(P16),1), $P:$P, "<="&EOMONTH(P16,0))>10), TEXT(P16, "MMMM"), "") | X16: {=IF(AND(P16<>"", P16>=DATE(YEAR(P16),MONTH(P16),1), SUMIFS($K:$K, $C:$C, C16, $P:$P, ">="&DATE(YEAR(P16),MONTH(P16),1), $P:$P, "<="&EOMONTH(P16,0))>10), _xlfn.TEXTJOIN(", ", TRUE, _xlfn._xlws.FILTER($R:$R, ($C:$C=C16) * ($P:$P>=DATE(YEAR(P16),MONTH(P16),1)) * ($P:$P<=EOMONTH(P16,0)))), "")} | Y16: {=IF(AND(P16<>"", P16>=DATE(YEAR(P16),MONTH(P16),1), SUMIFS($K:$K, $C:$C, C16, $P:$P, ">="&DATE(YEAR(P16),MONTH(P16),1), $P:$P, "<="&EOMONTH(P16,0))>10), _xlfn.TEXTJOIN(", ", TRUE, _xlfn._xlws.FILTER($S:$S, ($C:$C=C16) * ($P:$P>=DATE(YEAR(P16),MONTH(P16),1)) * ($P:$P<=EOMONTH(P16,0)))), "")}
A17: 10 | B17: TEMPOACTIVA | C17: =_xlfn.XLOOKUP(D17,[1]!Data[CEDULA],[1]!Data[Nombre Completo],"No Existe",0,1) -> ELIANA GISSELA CHARRIS GARCIA | D17: 1044392082 | E17: =IFERROR(_xlfn.NUMBERVALUE(Data[[#This Row],[CEDULA ]],",","."),_xlfn.NUMBERVALUE(Data[[#This Row],[CEDULA ]],".",",")) -> 1044392082 | F17: =_xlfn.XLOOKUP(E17,[1]!Data[CEDULA],[1]!Data[CARGO],"No Existe",0,1) -> AUXILIAR DE COCINA | G17: =_xlfn.XLOOKUP(E17,[1]!Data[CEDULA],[1]!Data[EMPRESA DONDE PRESTA SERVICIO],"No Existe",0,1) -> COMFAMILIAR ATLANTICO | H17: =_xlfn.XLOOKUP(E17,[1]!Data[CEDULA],[1]!Data[UBICACIÓN],"No Existe",0,1) -> TURIPANA MERCADEO | I17: MUJER | J17: =UPPER(TEXT(Data[[#This Row],[F. INICIO]],"mmmm")) -> ENERO | K17: 2 | L17: EPS | M17: ENFERMENDAD GENERAL | N17: =_xlfn.XLOOKUP(D17,[1]!Data[CEDULA],[1]!Data[EPS/SURA],"No Existe",0,1) -> NUEVA E.P.S. | O17: =YEAR(Data[[#This Row],[F. INICIO]]) -> 2024 | P17: 45298 | Q17: 45299 | R17: R101 | S17: =IF(Data[[#This Row],[TIPO DE INCAPACIDAD]]="LICENCIA DE PATERNIDAD","Licencia de paternidad",IF(Data[[#This Row],[TIPO DE INCAPACIDAD]]="LICENCIA DE LUTO","Licencia de Luto",_xlfn.IFNA(VLOOKUP(R17,'CIE-10 PARA RIPS'!$A$6:B13183,2,0),"No especificado"))) -> Dolor abdominal localizado en parte superior | T17: =IF(P17<>"", IF(P17>0, IF(P17<=DATE(YEAR(P17),MONTH(P17),DAY(P17)), IF(P17>=DATE(YEAR(P17),MONTH(P17),1), IF(K17>10, C17, IF(SUMIFS($K:$K, $C:$C, C17, $P:$P, ">="&DATE(YEAR(P17),MONTH(P17),1), $P:$P, "<="&EOMONTH(P17,0))>10, C17, "")), ""))), "") | U17: =IF(AND(P17<>"", P17>=DATE(YEAR(P17),MONTH(P17),1), SUMIFS($K:$K, $C:$C, C17, $P:$P, ">="&DATE(YEAR(P17),MONTH(P17),1), $P:$P, "<="&EOMONTH(P17,0))>10), K17, "") | V17: =IF(AND(P17<>"", P17>=DATE(YEAR(P17),MONTH(P17),1), SUMIFS($K:$K, $C:$C, C17, $P:$P, ">="&DATE(YEAR(P17),MONTH(P17),1), $P:$P, "<="&EOMONTH(P17,0))>10), YEAR(P17), "") | W17: =IF(AND(P17<>"", P17>=DATE(YEAR(P17),MONTH(P17),1), SUMIFS($K:$K, $C:$C, C17, $P:$P, ">="&DATE(YEAR(P17),MONTH(P17),1), $P:$P, "<="&EOMONTH(P17,0))>10), TEXT(P17, "MMMM"), "") | X17: {=IF(AND(P17<>"", P17>=DATE(YEAR(P17),MONTH(P17),1), SUMIFS($K:$K, $C:$C, C17, $P:$P, ">="&DATE(YEAR(P17),MONTH(P17),1), $P:$P, "<="&EOMONTH(P17,0))>10), _xlfn.TEXTJOIN(", ", TRUE, _xlfn._xlws.FILTER($R:$R, ($C:$C=C17) * ($P:$P>=DATE(YEAR(P17),MONTH(P17),1)) * ($P:$P<=EOMONTH(P17,0)))), "")} | Y17: {=IF(AND(P17<>"", P17>=DATE(YEAR(P17),MONTH(P17),1), SUMIFS($K:$K, $C:$C, C17, $P:$P, ">="&DATE(YEAR(P17),MONTH(P17),1), $P:$P, "<="&EOMONTH(P17,0))>10), _xlfn.TEXTJOIN(", ", TRUE, _xlfn._xlws.FILTER($S:$S, ($C:$C=C17) * ($P:$P>=DATE(YEAR(P17),MONTH(P17),1)) * ($P:$P<=EOMONTH(P17,0)))), "")}
A18: 11 | B18: TEMPOACTIVA | C18: =_xlfn.XLOOKUP(D18,[1]!Data[CEDULA],[1]!Data[Nombre Completo],"No Existe",0,1) -> MARICELA CALDERIN PERTUZ | D18: 32869679 | E18: =IFERROR(_xlfn.NUMBERVALUE(Data[[#This Row],[CEDULA ]],",","."),_xlfn.NUMBERVALUE(Data[[#This Row],[CEDULA ]],".",",")) -> 32869679 | F18: =_xlfn.XLOOKUP(E18,[1]!Data[CEDULA],[1]!Data[CARGO],"No Existe",0,1) -> SUPERNUMERARIO(A) | G18: =_xlfn.XLOOKUP(E18,[1]!Data[CEDULA],[1]!Data[EMPRESA DONDE PRESTA SERVICIO],"No Existe",0,1) -> COMFAMILIAR ATLANTICO | H18: =_xlfn.XLOOKUP(E18,[1]!Data[CEDULA],[1]!Data[UBICACIÓN],"No Existe",0,1) -> SEDE CARIBE | I18: MUJER | J18: =UPPER(TEXT(Data[[#This Row],[F. INICIO]],"mmmm")) -> ENERO | K18: 1 | L18: EPS | M18: ENFERMENDAD GENERAL | N18: =_xlfn.XLOOKUP(D18,[1]!Data[CEDULA],[1]!Data[EPS/SURA],"No Existe",0,1) -> EPS/SURA | O18: =YEAR(Data[[#This Row],[F. INICIO]]) -> 2024 | P18: 45295 | Q18: 45295 | R18: H82X | S18: =IF(Data[[#This Row],[TIPO DE INCAPACIDAD]]="LICENCIA DE PATERNIDAD","Licencia de paternidad",IF(Data[[#This Row],[TIPO DE INCAPACIDAD]]="LICENCIA DE LUTO","Licencia de Luto",_xlfn.IFNA(VLOOKUP(R18,'CIE-10 PARA RIPS'!$A$6:B13184,2,0),"No especificado"))) -> Sindromes vertiginosos en enfermedades clasificadas en otra parte | T18: =IF(P18<>"", IF(P18>0, IF(P18<=DATE(YEAR(P18),MONTH(P18),DAY(P18)), IF(P18>=DATE(YEAR(P18),MONTH(P18),1), IF(K18>10, C18, IF(SUMIFS($K:$K, $C:$C, C18, $P:$P, ">="&DATE(YEAR(P18),MONTH(P18),1), $P:$P, "<="&EOMONTH(P18,0))>10, C18, "")), ""))), "") | U18: =IF(AND(P18<>"", P18>=DATE(YEAR(P18),MONTH(P18),1), SUMIFS($K:$K, $C:$C, C18, $P:$P, ">="&DATE(YEAR(P18),MONTH(P18),1), $P:$P, "<="&EOMONTH(P18,0))>10), K18, "") | V18: =IF(AND(P18<>"", P18>=DATE(YEAR(P18),MONTH(P18),1), SUMIFS($K:$K, $C:$C, C18, $P:$P, ">="&DATE(YEAR(P18),MONTH(P18),1), $P:$P, "<="&EOMONTH(P18,0))>10), YEAR(P18), "") | W18: =IF(AND(P18<>"", P18>=DATE(YEAR(P18),MONTH(P18),1), SUMIFS($K:$K, $C:$C, C18, $P:$P, ">="&DATE(YEAR(P18),MONTH(P18),1), $P:$P, "<="&EOMONTH(P18,0))>10), TEXT(P18, "MMMM"), "") | X18: {=IF(AND(P18<>"", P18>=DATE(YEAR(P18),MONTH(P18),1), SUMIFS($K:$K, $C:$C, C18, $P:$P, ">="&DATE(YEAR(P18),MONTH(P18),1), $P:$P, "<="&EOMONTH(P18,0))>10), _xlfn.TEXTJOIN(", ", TRUE, _xlfn._xlws.FILTER($R:$R, ($C:$C=C18) * ($P:$P>=DATE(YEAR(P18),MONTH(P18),1)) * ($P:$P<=EOMONTH(P18,0)))), "")} | Y18: {=IF(AND(P18<>"", P18>=DATE(YEAR(P18),MONTH(P18),1), SUMIFS($K:$K, $C:$C, C18, $P:$P, ">="&DATE(YEAR(P18),MONTH(P18),1), $P:$P, "<="&EOMONTH(P18,0))>10), _xlfn.TEXTJOIN(", ", TRUE, _xlfn._xlws.FILTER($S:$S, ($C:$C=C18) * ($P:$P>=DATE(YEAR(P18),MONTH(P18),1)) * ($P:$P<=EOMONTH(P18,0)))), "")}
A19: 12 | B19: TEMPOACTIVA | C19: =_xlfn.XLOOKUP(D19,[1]!Data[CEDULA],[1]!Data[Nombre Completo],"No Existe",0,1) -> DIONI DE JESUS ECHEVERRIA CASTRO | D19: 1129566741 | E19: =IFERROR(_xlfn.NUMBERVALUE(Data[[#This Row],[CEDULA ]],",","."),_xlfn.NUMBERVALUE(Data[[#This Row],[CEDULA ]],".",",")) -> 1129566741 | F19: =_xlfn.XLOOKUP(E19,[1]!Data[CEDULA],[1]!Data[CARGO],"No Existe",0,1) -> COCINERO 1 | G19: =_xlfn.XLOOKUP(E19,[1]!Data[CEDULA],[1]!Data[EMPRESA DONDE PRESTA SERVICIO],"No Existe",0,1) -> COMFAMILIAR ATLANTICO | H19: =_xlfn.XLOOKUP(E19,[1]!Data[CEDULA],[1]!Data[UBICACIÓN],"No Existe",0,1) -> SEDE NORTE MERCADEO | I19: HOMBRE | J19: =UPPER(TEXT(Data[[#This Row],[F. INICIO]],"mmmm")) -> ENERO | K19: 2 | L19: EPS | M19: ENFERMENDAD GENERAL | N19: =_xlfn.XLOOKUP(D19,[1]!Data[CEDULA],[1]!Data[EPS/SURA],"No Existe",0,1) -> SALUD TOTAL | O19: =YEAR(Data[[#This Row],[F. INICIO]]) -> 2024 | P19: 45292 | Q19: 45293 | R19: A90X | S19: =IF(Data[[#This Row],[TIPO DE INCAPACIDAD]]="LICENCIA DE PATERNIDAD","Licencia de paternidad",IF(Data[[#This Row],[TIPO DE INCAPACIDAD]]="LICENCIA DE LUTO","Licencia de Luto",_xlfn.IFNA(VLOOKUP(R19,'CIE-10 PARA RIPS'!$A$6:B13185,2,0),"No especificado"))) -> Ciertas enfermedades infecciosas y parasitarias (A00-B99). | T19: =IF(P19<>"", IF(P19>0, IF(P19<=DATE(YEAR(P19),MONTH(P19),DAY(P19)), IF(P19>=DATE(YEAR(P19),MONTH(P19),1), IF(K19>10, C19, IF(SUMIFS($K:$K, $C:$C, C19, $P:$P, ">="&DATE(YEAR(P19),MONTH(P19),1), $P:$P, "<="&EOMONTH(P19,0))>10, C19, "")), ""))), "") | U19: =IF(AND(P19<>"", P19>=DATE(YEAR(P19),MONTH(P19),1), SUMIFS($K:$K, $C:$C, C19, $P:$P, ">="&DATE(YEAR(P19),MONTH(P19),1), $P:$P, "<="&EOMONTH(P19,0))>10), K19, "") | V19: =IF(AND(P19<>"", P19>=DATE(YEAR(P19),MONTH(P19),1), SUMIFS($K:$K, $C:$C, C19, $P:$P, ">="&DATE(YEAR(P19),MONTH(P19),1), $P:$P, "<="&EOMONTH(P19,0))>10), YEAR(P19), "") | W19: =IF(AND(P19<>"", P19>=DATE(YEAR(P19),MONTH(P19),1), SUMIFS($K:$K, $C:$C, C19, $P:$P, ">="&DATE(YEAR(P19),MONTH(P19),1), $P:$P, "<="&EOMONTH(P19,0))>10), TEXT(P19, "MMMM"), "") | X19: {=IF(AND(P19<>"", P19>=DATE(YEAR(P19),MONTH(P19),1), SUMIFS($K:$K, $C:$C, C19, $P:$P, ">="&DATE(YEAR(P19),MONTH(P19),1), $P:$P, "<="&EOMONTH(P19,0))>10), _xlfn.TEXTJOIN(", ", TRUE, _xlfn._xlws.FILTER($R:$R, ($C:$C=C19) * ($P:$P>=DATE(YEAR(P19),MONTH(P19),1)) * ($P:$P<=EOMONTH(P19,0)))), "")} | Y19: {=IF(AND(P19<>"", P19>=DATE(YEAR(P19),MONTH(P19),1), SUMIFS($K:$K, $C:$C, C19, $P:$P, ">="&DATE(YEAR(P19),MONTH(P19),1), $P:$P, "<="&EOMONTH(P19,0))>10), _xlfn.TEXTJOIN(", ", TRUE, _xlfn._xlws.FILTER($S:$S, ($C:$C=C19) * ($P:$P>=DATE(YEAR(P19),MONTH(P19),1)) * ($P:$P<=EOMONTH(P19,0)))), "")}
